Workbook

Sheet Algorithm Details
B1: +Visual = Improved visual framework | C1: RA: Research Academic | E1: R = Required | J1: L = Limited to certain models | M1: Mech. = Mechanical (H.FoV = 360 deg.)
B2: +LiDAR = Improved LiDAR framework | C2: C: Comercial | E2: O = Optional | J2: N/S = Not Specified | M2: SSL = Solid State LiDAR (H.FoV < 360 deg.) | Y2: Year < 2019
E3: S = Supported | M3: Both = both types are supported
E4: Sensor type | X4: Last activity | AC4: Additional notes:
A5: SLAM Algorithm | B5: ROS | C5: FOSS | D5: Visual-LiDAR Fusion type | E5: LiDAR | F5: Visual | G5: IMU | H5: GPS | I5: Additional Odometry sources | J5: LiDAR Type & FoV | K5: LiDAR Dimensionality | L5: fish-eye | M5: Mono | N5: Stereo | O5: (depth) RGB-D | P5: IMU axis | Q5: Re-localization | R5: Pure localization | S5: Loop-Closure | T5: Map features/ descriptors/ segmentation | U5: Resources for navigation | V5: Computational resource information (system used by the authors, not a system requirement) | W5: Documentation | X5: (years) | Y5: (Date) | Z5: Docker | AA5: Evaluated with well known public datasets | AB5: Paper (DOI)
A6: ORB-SLAM | B6: ROS1 EOL (Fuerte, Groovy, Hydro) | C6: RA: GPL v3 C: undisclosed | D6: - | E6: - | F6: R | G6: - | H6: - | I6: - | J6: - | K6: - | L6: - | M6: S | N6: - | O6: - | P6: - | Q6: S | S6: S | T6: ORB | V6: uses 3 threads | W6: github | X6: =YEAR(TODAY())-YEAR(Y6) -> 10 | Y6: 42718 | Z6: - | AA6: + | AB6: 10.1109/TRO.2015.2463671
A7: ORB-SLAM2 | B7: ROS1 EOL (Hydro) | C7: RA: GPL v3 C: undisclosed | D7: - | E7: - | F7: R | G7: - | H7: - | I7: - | J7: - | K7: - | L7: - | M7: S | N7: S | O7: S | P7: - | Q7: S | R7: S | S7: S | T7: ORB | V7: Uses 4 threads | W7: github | X7: =YEAR(TODAY())-YEAR(Y7) -> 9 | Y7: 43019 | Z7: - | AA7: + | AB7: 10.1109/TRO.2017.2705103 | AC7: Does not require GPU
A8: MapLab 2.0 | B8: ROS1 (Melodic) | C8: Apache 2.0 | E8: O | F8: R | G8: R | H8: O | K8: 3D | M8: S | N8: S | P8: 6-axis | R8: S | S8: S | W8: website, github | X8: =YEAR(TODAY())-YEAR(Y8) -> 3 | Y8: 45095 | Z8: - | AA8: + | AB8: 10.1109/LRA.2018.2800113 10.1109/LRA.2022.3227865 | AC8: Multi-robot mapping
A9: LDSO | B9: - | C9: GPL v3 | D9: - | E9: - | F9: R | G9: - | H9: - | I9: - | J9: =E9 -> - | K9: =J9 -> - | L9: - | M9: S | N9: - | O9: - | P9: - | R9: - | S9: S | T9: DSO | V9: Can run in real time with i7-4770HQ CPU and 16GB RAM | W9: github | X9: =YEAR(TODAY())-YEAR(Y9) -> 6 | Y9: 43966 | Z9: - | AA9: + | AB9: 10.1109/IROS.2018.8593376
A10: VINS-Mono | B10: ROS1 (kinetic) | C10: GPL v3 | D10: - | E10: - | F10: R | G10: R | H10: - | I10: - | J10: =E10 -> - | K10: =J10 -> - | L10: - | M10: S | N10: - | O10: - | P10: 6-axis | Q10: S | R10: - | S10: S | T10: KLT sparse optical flow algorithm | U10: map-merging | V10: Can run in real time with i7-4790 CPU@3.6GHz | W10: github | X10: =YEAR(TODAY())-YEAR(Y10) -> 7 | Y10: 43537 | Z10: + | AA10: + | AB10: 10.1109/TRO.2018.2853729
A11: VINS-Fusion | B11: ROS1 (kinetic, Melodic) | C11: GPL v3 | D11: - | E11: - | F11: R | G11: O | H11: O | I11: - | J11: =E11 -> - | K11: =J11 -> - | L11: S | M11: S | N11: S | O11: - | P11: ?-axis | Q11: S | R11: - | S11: S | V11: Can run in real time with i7-4790 CPU@3.6GHz | W11: github | X11: =YEAR(TODAY())-YEAR(Y11) -> 5 | Y11: 44403 | Z11: + | AA11: + | AC11: (extension of VINS-Mono)
A12: OpenVSLAM | B12: ROS1 (Noetic), ROS2 (humble, foxy, galactic) | C12: BSD 2-Clause | D12: - | E12: - | F12: R | G12: - | H12: - | I12: - | J12: =E12 -> - | K12: =J12 -> - | L12: S | M12: S | N12: S | O12: S | P12: - | R12: S | S12: S | T12: FAST (corner detection method) | V12: Can run in real time with i7-7820HK CPU@2.9GHz, 32GB RAM | W12: web-page, github | X12: =YEAR(TODAY())-YEAR(Y12) -> 4 | Y12: 44886 | Z12: + | AA12: + | AB12: 10.1145/3343031.3350539
A13: Basalt | B13: ROS1 (Noetic) | C13: BSD 3-Clause | D13: - | E13: - | F13: R | G13: R | H13: - | I13: - | J13: =E13 -> - | K13: =J13 -> - | L13: - | M13: - | N13: S | O13: - | S13: S | T13: ORB | V13: Can run in real time with Intel E5-1620 CPU (4 cores) | W13: github | X13: =YEAR(TODAY())-YEAR(Y13) -> 3 | Y13: 44951 | Z13: + | AA13: + | AB13: 10.1109/LRA.2019.2961227 | AC13: VIO algorithm
A14: Kimera | B14: ROS1 (Melodic) | C14: BSD 2-Clause "Simplified" | D14: - | E14: - | F14: R | G14: R | H14: - | I14: - | J14: =E14 -> - | K14: =J14 -> - | L14: - | M14: - | N14: S | O14: - | P14: ?-axis | Q14: - | S14: S | U14: Semantic labelling | V14: Uses 4 parallel threads | W14: github | X14: =YEAR(TODAY())-YEAR(Y14) -> 5 | Y14: 44377 | Z14: + | AA14: EuRoC only | AB14: 10.1109/ICRA40945.2020.9196885 | AC14: "produces a 3D metric-semantic mesh from semantically labeled images, which can be obtained by modern deep learning methods."
A15: OpenVINS | B15: ROS1 (Kinetic, Melodic, Noetic), ROS2 (Dashing, Galatic) | C15: GPL v3 | D15: - | E15: - | F15: R | G15: R | H15: - | I15: - | J15: =E15 -> - | K15: =J15 -> - | L15: - | M15: S | N15: S | O15: - | P15: ?-axis | S15: S | W15: web-page, github | X15: =YEAR(TODAY())-YEAR(Y15) -> 3 | Y15: 45097 | Z15: - | AA15: + | AB15: 10.1109/ICRA40945.2020.9196524
A16: ORB-SLAM3 | B16: ROS1 (Melodic, Noetic) | C16: GPL v3 | D16: - | E16: - | F16: R | G16: R | J16: =E16 -> - | K16: =J16 -> - | L16: S | M16: S | N16: S | O16: S | P16: ?axis | Q16: S | R16: S | S16: S | T16: ORB | V16: Can run in real time at 30~40 frames with i7-7700 CPU@3.6GHz 32GB RAM (no GPU) | W16: github | X16: =YEAR(TODAY())-YEAR(Y16) -> 4 | Y16: 44602 | Z16: + | AA16: + | AB16: 10.1109/TRO.2021.3075644
A17: DRE-SLAM | B17: ROS1 (Kinetic) | C17: GPL v3 | D17: - | E17: - | F17: R | G17: - | H17: - | I17: (R) 2 wheel encoder | J17: - | K17: - | L17: - | M17: - | N17: S | O17: S | P17: - | S17: S | T17: ORB | U17: Builds OctoMap, removes dynamic objects pixels from image | V17: Can run in real time with i7-8700 and 16GB RAM (no GPU) | W17: github | X17: =YEAR(TODAY())-YEAR(Y17) -> 7 | Y17: 43542 | Z17: - | AA17: - | AB17: 10.3390/rs11040380 | AC17: Specifically developed to handle dynamic environments. Does not inplement a CNN or DL.
A18: SVO | B18: ROS1 (Groovy, Hydro, Indigo) | C18: + | D18: - | E18: - | F18: R | G18: - | H18: - | I18: - | J18: - | K18: - | L18: S | M18: S | N18: S | O18: - | P18: - | Q18: S | R18: - | S18: - | T18: none | V18: Uses 2 CPU cores. | W18: github | X18: =YEAR(TODAY())-YEAR(Y18) -> 9 | Y18: 42864 | Z18: - | AA18: - | AB18: 10.1109/ICRA.2014.6906584 | AC18: It is designed as a pure visual odometry system (not a full SLAM system).
A19: DSO | B19: ROS1 (Hydro) | C19: + | D19: - | E19: - | F19: R | G19: - | H19: - | I19: - | J19: - | K19: - | L19: S | M19: S | N19: S | O19: - | P19: - | Q19: - | R19: - | S19: - | T19: none (direct VO) | V19: Can run in real time with i7-4910MQ | W19: github | X19: =YEAR(TODAY())-YEAR(Y19) -> 5 | Y19: 44263 | Z19: - | AA19: + | AB19: 10.1109/TPAMI.2017.2658577 | AC19: It is designed as a pure visual odometry system (not a full SLAM system).
A20: DynaSLAM | B20: - | C20: Attribution-NonCommercial 4.0 International | D20: - | E20: - | F20: R | G20: - | H20: - | I20: - | J20: - | K20: - | L20: - | M20: S | N20: S | O20: S | P20: - | Q20: S | S20: S | T20: ORB | U20: dynamic object detection and background inpainting | W20: github | X20: =YEAR(TODAY())-YEAR(Y20) -> 7 | Y20: 43633 | Z20: - | AA20: + | AB20: 10.1109/LRA.2018.2860039 | AC20: VSLAM. Built upon ORB-SLAM2. Can detect moving objects with DL, multiview-geometry or both.
A21: DynSLAM | B21: - | C21: BSD 3-Clause | D21: - | E21: - | F21: R | G21: - | H21: - | I21: - | J21: - | K21: - | L21: - | M21: - | N21: S | O21: - | P21: - | Q21: - | T21: simple blob features , corner features | U21: Implements CNN for semantic segmentation | V21: "Our system is able to run at approximately 2.5Hz on a PC equipped with an nVIDIA GeForce GTX 1080 GPU" | W21: github | X21: =YEAR(TODAY())-YEAR(Y21) -> 5 | Y21: 44469 | Z21: + | AA21: + | AB21: 10.1109/ICRA.2018.8462974 | AC21: https://siegedog.com/dynslam/
A22: RTAB-Map | B22: ROS1 (Noetic), ROS2 (Iron, Humble) | C22: Custom, free to use and modify | D22: +Visual | E22: O | F22: R | G22: - | H22: - | I22: O | J22: N/S | K22: 2D & 3D | L22: - | M22: - | N22: S | O22: S | P22: - | Q22: S | S22: S | T22: (multiple) SURF, SIFT, BRIEF, BRISK, KAZE, DAISY, SuperPoint. | U22: Builds OctoMap | V22: Can run in real time with: i7-9750H CPU, GTX 1650 GPU Multi-core CPU required | W22: web-page, github | X22: =YEAR(TODAY())-YEAR(Y22) -> 3 | Y22: 45207 | Z22: + | AA22: KITTI, EuRoC, TUM RGB-D, MIT Stata | AB22: https://introlab.github.io/rtabmap/ 10.3389/frobt.2022.801886 | AC22: Can use separate camera for obstacle detection.
A23: FAST-LIO2 | B23: ROS1 (Melodic, Noetic) | C23: GPL 2.0 | D23: - | E23: R | F23: - | G23: R | H23: - | I23: - | J23: L | K23: 3D | L23: - | M23: - | N23: - | O23: - | P23: 9-axis | Q23: S | R23: - | S23: S | V23: 0.5 ~ 0.2 Hz, IMU (200 Hz), LiDAR (10 Hz) [1.8GHz i7-8550U with 8GB RAM] [2.2GHz Cortex-A73 and 4GB RAM] | W23: github | X23: =YEAR(TODAY())-YEAR(Y23) -> 3 | Y23: 45211 | Z23: + | AA23: - | AB23: 10.1109/TRO.2022.3141876 | AC23: Uses a dynamic ikd-tree. Can often surpass LIO-SAM in terms of accuracy.
A24: LIO-SAM | B24: ROS1 (Kinetic, Melodic, Noetic), ROS2 (Foxy, Galactic, Humble) | C24: BSD 3-Clause | D24: - | E24: R | F24: - | G24: R | H24: O | I24: - | J24: L | K24: 3D | L24: - | M24: - | N24: - | O24: - | P24: 9-axis | Q24: - | R24: - | S24: S | T24: Planar and edge features from pointcloud | V24: Can run in real-time with i7-10710U CPU | W24: github | X24: =YEAR(TODAY())-YEAR(Y24) -> 4 | Y24: 44749 | Z24: + | AA24: - | AB24: 10.1109/IROS45743.2020.9341176
A25: DV-LOAM | B25: ROS1 (Kinetic, Melodic) | C25: Restricted by ORB-SLAM2 RA: GPLv3 C: undisclosed | D25: Concurrent | E25: R | F25: R | G25: - | H25: - | I25: - | J25: N/S | K25: 3D | L25: - | M25: S | N25: - | O25: - | P25: - | Q25: - | R25: - | S25: S | T25: "same multi-frame photometric optimization as DSO to estimate the poses of the keyframes" | W25: github | X25: =YEAR(TODAY())-YEAR(Y25) -> 5 | Y25: 44533 | AA25: + | AB25: 10.3390/rs13163340 | AC25: "combines a depth-enhanced direct visual odometry module and the LiDAR mapping module into location and mapping. It takes advantage of the efficiency of the direct VO module and the accuracy of LiDAR scan-to-map matching method"
A26: DVL-SLAM | B26: ROS1 (C++11, Lunar and below) | C26: Not specified | D26: +Visual | E26: R | F26: R | G26: - | H26: - | I26: - | J26: Mech. | K26: 3D | L26: - | M26: S | N26: - | O26: - | P26: - | Q26: - | R26: - | S26: S | T26: "same multi-frame photometric optimization as DSO to estimate the poses of the keyframes" | V26: Can run in real-time with i7-7700HQ and 8 GB RAM | W26: github | X26: =YEAR(TODAY())-YEAR(Y26) -> 7 | Y26: 43754 | AA26: - | AB26: 10.1007/s10514-019-09881-0 | AC26: "The key finding of this paper is that the direct method is more robust under sparse depth with narrow field of view"
A27: SDV-LOAM | B27: ROS1 (Ubuntu 16, unknown ROS ver. ) | C27: Not fully open-source | D27: +Visual | E27: R | F27: R | G27: - | H27: - | I27: - | J27: Mech. | K27: 3D | L27: - | M27: S | N27: - | O27: - | P27: - | Q27: - | R27: - | S27: S | W27: github | X27: =YEAR(TODAY())-YEAR(Y27) -> 3 | Y27: 45104 | Z27: - | AA27: KITTI | AB27: 10.1109/TPAMI.2023.3262817
A28: R2LIVE | B28: ROS1 (Kinetic, Melodic) | C28: RA: GPL2 C: undisclosed | D28: Concurrent | E28: R | F28: R | G28: R | H28: - | I28: - | J28: L | K28: 3D | L28: - | M28: S | N28: - | O28: - | P28: 6-axis | Q28: - | R28: - | S28: ? | V28: Can run in real-time at on-board system (i7-8550U, 8 GB RAM) | W28: github | X28: =YEAR(TODAY())-YEAR(Y28) -> 5 | Y28: 44418 | Z28: + | AA28: - | AB28: 10.1109/LRA.2021.3095515 | AC28: "Taking advantage of measurements from all individual sensors, our algorithm is robust enough to various visual failure, LiDAR-degenerated scenarios, and is able to run in real time on an on-board computation platform"
A29: R3LIVE | B29: ROS1 (Kinetic, Noetic) | C29: RA: GPL2 C: undisclosed | D29: Concurrent | E29: R | F29: R | G29: R | J29: L | K29: 3D | M29: S | P29: 6-axis | S29: ? | T29: Pixel colors and LiDAR geometry | V29: Can run in real-time at on-board system (i7-8550U, 8 GB RAM) | W29: github | X29: =YEAR(TODAY())-YEAR(Y29) -> 4 | Y29: 44736 | AA29: - | AB29: 10.1109/ICRA46639.2022.9811935
A30: cuVSLAM | B30: ROS2 (Humble) | C30: Apache 2.0 | D30: - | E30: - | F30: R | G30: O | H30: - | I30: - | J30: - | K30: - | L30: - | M30: - | N30: S | O30: - | P30: ?-axis | S30: S | V30: Can ruun in NVIDIA Jetson | W30: github, website | X30: =YEAR(TODAY())-YEAR(Y30) -> 3 | Y30: 45247 | Z30: - | AA30: - | AB30: doi.org/10.48550/arXiv.2506.04359
A31: DynaVINS | B31: ROS1 (Melodic) | C31: GPL v3 | D31: - | E31: - | F31: R | G31: R | H31: - | I31: - | J31: - | K31: - | L31: - | M31: S | N31: S | O31: - | P31: ?-axis | S31: S | T31: Feature based (feature type not specified) | W31: github | X31: =YEAR(TODAY())-YEAR(Y31) -> 4 | Y31: 44868 | AA31: VIODE | AB31: 10.1109/LRA.2022.3203231
A32: RDS-SLAM | B32: ROS1 (Melodic) | C32: GPL v3 | D32: - | E32: - | F32: R | G32: - | H32: - | I32: - | J32: - | K32: - | L32: - | M32: O | N32: O | O32: - | P32: - | Q32: - | R32: - | S32: S | T32: ORB | V32: GeForce RTX 2080Ti GPU, Cuda 11.1, | W32: github | X32: =YEAR(TODAY())-YEAR(Y32) -> 5 | Y32: 44472 | Z32: + | AA32: TUM RGB-D | AB32: 10.1109/ACCESS.2021.3050617
A33: DS-SLAM | B33: ROS1 (Hydro) | C33: RA: GPL v3 C: undisclosed | D33: - | E33: - | F33: R | G33: - | H33: - | I33: - | J33: - | K33: - | L33: - | M33: S | N33: S | O33: S | P33: - | Q33: S | R33: S | S33: S | T33: ORB | U33: octo-tree map | V33: i7 CPU, P4000 GPU, and 32GB RAM | W33: github | X33: =YEAR(TODAY())-YEAR(Y33) -> 8 | Y33: 43378 | Z33: - | AA33: TUM RGB-D | AB33: 0.1109/IROS.2018.8593691 | AC33: Based on ORB-SLAM2
A34: RS-SLAM | B34: ROS1 (Hydro) | C34: RA: GPL v3 C: undisclosed | D34: =D7 -> - | E34: =E7 -> - | F34: =F7 -> R | G34: =G7 -> - | H34: =H7 -> - | I34: =I7 -> - | J34: =J7 -> - | K34: =K7 -> - | ... S34: =S7 -> S | T34: ORB | U34: OctoMap | V34: i5-7500 CPU, Nvidia GTX 1060 GPU, 16 GB RAM | W34: github | X34: =YEAR(TODAY())-YEAR(Y34) -> 7 | Y34: 43735 | Z34: - | AA34: TUM RGB-D | AB34: 10.1109/JSEN.2021.3099511 | AC34: Based on ORB-SLAM2
A35: LeGO-LOAM | B35: ROS1 (kinetic, melodic) | C35: BSD 3-Clause | D35: - | E35: R | F35: - | G35: - | I35: - | L35: - | M35: - | N35: - | O35: - | W35: github | X35: =YEAR(TODAY())-YEAR(Y35) -> 6 | Y35: 43909 | AB35: 10.1109/IROS.2018.8594299
A36: HDL Graph SLAM | B36: ROS1 (Melodic, Noetic) | C36: BSD 2-Clause | D36: - | E36: R | F36: - | G36: O | H36: O | I36: - | K36: 3D | L36: - | M36: - | N36: - | O36: - | Q36: - | R36: - | S36: S | W36: github | X36: =YEAR(TODAY())-YEAR(Y36) -> 3 | Y36: 44985 | AB36: doi.org/10.1177/1729881419841532
A37: GLIM | B37: ROS1, ROS2 | C37: RA: GPL v3 C: undisclosed | D37: - | E37: R | F37: O | G37: R | H37: O* | I37: - | J37: Both | K37: 3D | L37: S | M37: S | N37: - | O37: - | P37: 3-axis | S37: O | T37: - | U37: - | V37: CUDA supported | W37: github | X37: =YEAR(TODAY())-YEAR(Y37) -> 2 | Y37: 45557 | Z37: + | AA37: NTU_VIRAL, | AB37: doi.org/10.1016/j.robot.2024.104750 | AC37: *Extension modules are available to add functionallity.
A38: SLICT | B38: ROS1 (Noetic) | C38: RA: GPL 2.0 C: GPL 2.0 | D38: - | E38: R | F38: - | G38: R | I38: - | J38: Both | K38: 3D | L38: - | M38: - | N38: - | O38: - | Q38: S | R38: - | S38: S | W38: github | X38: =YEAR(TODAY())-YEAR(Y38) -> 2 | Y38: 45526 | Z38: + | AB38: 10.1109/LRA.2023.3246390
A39: MARS | B39: ROS1 | C39: RA: BSD 3-Clause C: BSD 3-Clause | D39: - | E39: R | F39: - | G39: S | H39: S | I39: - | J39: Mech | K39: 3D | L39: - | M39: - | N39: - | O39: - | R39: - | S39: - | V39: Runs on CPU only | W39: github | X39: =YEAR(TODAY())-YEAR(Y39) -> 2 | Y39: 45478 | AA39: UrbanLoco, Newer College, Oxford, LIVE, | AB39: 10.1109/IROS51168.2021.9636763
A40: VoxelMap | B40: Ros1 (Noetic) | C40: RA: GPL 2.0 C: undisclosed | D40: - | E40: R | F40: - | G40: R | H40: - | I40: - | J40: Both | K40: 3D | L40: - | M40: - | N40: - | O40: - | Q40: - | R40: - | S40: - | T40: Each voxel stores one plane feature | V40: Intel i7-10700 @ 2.9 GHz with 16 GB RAM and Nvidia GeForce GTX 730 with 2 GB VRAM | W40: github | X40: =YEAR(TODAY())-YEAR(Y40) -> 4 | Y40: 44722 | Z40: - | AA40: KITTI | AB40: 10.1109/LRA.2022.3187250
...

Sheet Data
A3: Algoritmos com o menor erro | B3: =INDEX($A$25:$A$118, MATCH(SMALL(B25:B118,1), B25:B118, 0)) -> Basalt | C3: =INDEX($A$25:$A$118, MATCH(SMALL(C25:C118,1), C25:C118, 0)) -> Basalt | D3: =INDEX($A$25:$A$118, MATCH(SMALL(D25:D118,1), D25:D118, 0)) -> Basalt | E3: =INDEX($A$25:$A$118, MATCH(SMALL(E25:E118,1), E25:E118, 0)) -> LDSO | F3: =INDEX($A$25:$A$118, MATCH(SMALL(F25:F118,1), F25:F118, 0)) -> ORB-SLAM3 | G3: =INDEX($A$25:$A$118, MATCH(SMALL(G25:G118,1), G25:G118, 0)) -> OpenVSLAM | H3: =INDEX($A$25:$A$118, MATCH(SMALL(H25:H118,1), H25:H118, 0)) -> Basalt | I3: =INDEX($A$25:$A$118, MATCH(SMALL(I25:I118,1), I25:I118, 0)) -> Basalt | ... DZ3: =INDEX($A$25:$A$118, MATCH(SMALL(DZ25:DZ118,1), DZ25:DZ118, 0)) -> HDL_Graph_SLAM | EC3: =INDEX($A$25:$A$118, MATCH(SMALL(EC25:EC118,1), EC25:EC118, 0)) -> ORB-SLAM3 | EF3: =INDEX($A$25:$A$118, MATCH(SMALL(EF25:EF118,1), EF25:EF118, 0)) -> Basalt | EH3: =INDEX($A$25:$A$118, MATCH(SMALL(EH25:EH118,1), EH25:EH118, 0)) -> Kimera | EI3: =INDEX($A$25:$A$118, MATCH(SMALL(EI25:EI118,1), EI25:EI118, 0)) -> DV-LOAM | EJ3: =INDEX($A$25:$A$118, MATCH(SMALL(EJ25:EJ118,1), EJ25:EJ118, 0)) -> RTAB. Stereo. ORB2 | EK3: =INDEX($A$25:$A$118, MATCH(SMALL(EK25:EK118,1), EK25:EK118, 0)) -> RTAB. Stereo. ORB2 | EL3: =INDEX($A$25:$A$118, MATCH(SMALL(EL25:EL118,1), EL25:EL118, 0)) -> RTAB. Stereo. ORB2 | EM3: =INDEX($A$25:$A$118, MATCH(SMALL(EM25:EM118,1), EM25:EM118, 0)) -> RTAB. Stereo. F2F | EN3: =INDEX($A$25:$A$118, MATCH(SMALL(EN25:EN118,1), EN25:EN118, 0)) -> RTAB. Stereo. ORB2 | EO3: =INDEX($A$25:$A$118, MATCH(SMALL(EO25:EO118,1), EO25:EO118, 0)) -> RTAB. Stereo. ORB2 | EP3: =INDEX($A$25:$A$118, MATCH(SMALL(EP25:EP118,1), EP25:EP118, 0)) -> DV-LOAM | EQ3: =IFERROR(INDEX($A$25:$A$118, MATCH(SMALL(EQ25:EQ118,1), EQ25:EQ118, 0)),"") -> DV-LOAM | ER3: =IFERROR(INDEX($A$25:$A$118, MATCH(SMALL(ER25:ER118,1), ER25:ER118, 0)),"") -> DVL-SLAM | ES3: =IFERROR(INDEX($A$25:$A$126, MATCH(SMALL(ES25:ES126,1), ES25:ES126, 0)),"") -> RTAB. Stereo. F2M | ET3: =IFERROR(INDEX($A$25:$A$126, MATCH(SMALL(ET25:ET126,1), ET25:ET126, 0)),"") -> VINS-Mono | EU3: =IFERROR(INDEX($A$25:$A$126, MATCH(SMALL(EU25:EU126,1), EU25:EU126, 0)),"") -> VINS-Mono | EV3: =IFERROR(INDEX($A$25:$A$126, MATCH(SMALL(EV25:EV126,1), EV25:EV126, 0)),"") -> OKVIS | EW3: =IFERROR(INDEX($A$25:$A$126, MATCH(SMALL(EW25:EW126,1), EW25:EW126, 0)),"") -> VINS-Mono | EX3: =IFERROR(INDEX($A$25:$A$126, MATCH(SMALL(EX25:EX126,1), EX25:EX126, 0)),"") -> VINS-Mono | EY3: =IFERROR(INDEX($A$25:$A$126, MATCH(SMALL(EY25:EY126,1), EY25:EY126, 0)),"") -> VINS-Mono | EZ3: =IFERROR(INDEX($A$25:$A$126, MATCH(SMALL(EZ25:EZ126,1), EZ25:EZ126, 0)),"") -> VINS-Mono | ... IJ3: =IFERROR(INDEX($A$25:$A$126, MATCH(SMALL(IJ25:IJ126,1), IJ25:IJ126, 0)),"") -> ORB-SLAM2 | IK3: =IFERROR(INDEX($A$25:$A$200, MATCH(SMALL(IK25:IK200,1), IK25:IK200, 0)),"") -> ORB-SLAM2 | IL3: =IFERROR(INDEX($A$25:$A$200, MATCH(SMALL(IL25:IL200,1), IL25:IL200, 0)),"") -> Plane-Edge-SLAM | IM3: =IFERROR(INDEX($A$25:$A$200, MATCH(SMALL(IM25:IM200,1), IM25:IM200, 0)),"") -> ORB-SLAM2 | IN3: =IFERROR(INDEX($A$25:$A$200, MATCH(SMALL(IN25:IN200,1), IN25:IN200, 0)),"") -> ORB-SLAM2 | IO3: =IFERROR(INDEX($A$25:$A$200, MATCH(SMALL(IO25:IO200,1), IO25:IO200, 0)),"") -> ORB-SLAM2 | IP3: =IFERROR(INDEX($A$25:$A$200, MATCH(SMALL(IP25:IP200,1), IP25:IP200, 0)),"") -> BundleFusion | IQ3: =IFERROR(INDEX($A$25:$A$200, MATCH(SMALL(IQ25:IQ200,1), IQ25:IQ200, 0)),"") -> ORB-SLAM2 | IR3: =IFERROR(INDEX($A$25:$A$200, MATCH(SMALL(IR25:IR200,1), IR25:IR200, 0)),"") -> DVO-SLAM | ... AGQ3: =IFERROR(INDEX($A$25:$A$200, MATCH(SMALL(AGQ25:AGQ200,1), AGQ25:AGQ200, 0)),"") -> DynaVINS
B4: {=IFERROR(INDEX($A$25:$A$118, MATCH(1,(B25:B118=SMALL(B25:B118,1))*(COUNTIF(B3, $A$25:$A$118)=0),0)), "")} | C4: {=IFERROR(INDEX($A$25:$A$118, MATCH(1,(C25:C118=SMALL(C25:C118,1))*(COUNTIF(C3, $A$25:$A$118)=0),0)), "")} -> ORB-SLAM3 | D4: {=IFERROR(INDEX($A$25:$A$118, MATCH(1,(D25:D118=SMALL(D25:D118,1))*(COUNTIF(D3, $A$25:$A$118)=0),0)), "")} | E4: {=IFERROR(INDEX($A$25:$A$118, MATCH(1,(E25:E118=SMALL(E25:E118,1))*(COUNTIF(E3, $A$25:$A$118)=0),0)), "")} | F4: {=IFERROR(INDEX($A$25:$A$118, MATCH(1,(F25:F118=SMALL(F25:F118,1))*(COUNTIF(F3, $A$25:$A$118)=0),0)), "")} | G4: {=IFERROR(INDEX($A$25:$A$118, MATCH(1,(G25:G118=SMALL(G25:G118,1))*(COUNTIF(G3, $A$25:$A$118)=0),0)), "")} -> ORB-SLAM3 | H4: {=IFERROR(INDEX($A$25:$A$118, MATCH(1,(H25:H118=SMALL(H25:H118,1))*(COUNTIF(H3, $A$25:$A$118)=0),0)), "")} | I4: {=IFERROR(INDEX($A$25:$A$118, MATCH(1,(I25:I118=SMALL(I25:I118,1))*(COUNTIF(I3, $A$25:$A$118)=0),0)), "")} | ... DZ4: {=IFERROR(INDEX($A$25:$A$118, MATCH(1,(DZ25:DZ118=SMALL(DZ25:DZ118,1))*(COUNTIF(DZ3, $A$25:$A$118)=0),0)), "")} | EC4: {=IFERROR(INDEX($A$25:$A$118, MATCH(1,(EC25:EC118=SMALL(EC25:EC118,1))*(COUNTIF(EC3, $A$25:$A$118)=0),0)), "")} | EF4: {=IFERROR(INDEX($A$25:$A$118, MATCH(1,(EF25:EF118=SMALL(EF25:EF118,1))*(COUNTIF(EF3, $A$25:$A$118)=0),0)), "")} | EH4: {=IFERROR(INDEX($A$25:$A$118, MATCH(1,(EH25:EH118=SMALL(EH25:EH118,1))*(COUNTIF(EH3, $A$25:$A$118)=0),0)), "")} | EI4: {=IFERROR(INDEX($A$25:$A$118, MATCH(1,(EI25:EI118=SMALL(EI25:EI118,1))*(COUNTIF(EI3, $A$25:$A$118)=0),0)), "")} | EJ4: {=IFERROR(INDEX($A$25:$A$118, MATCH(1,(EJ25:EJ118=SMALL(EJ25:EJ118,1))*(COUNTIF(EJ3, $A$25:$A$118)=0),0)), "")} | EK4: {=IFERROR(INDEX($A$25:$A$118, MATCH(1,(EK25:EK118=SMALL(EK25:EK118,1))*(COUNTIF(EK3, $A$25:$A$118)=0),0)), "")} | EL4: {=IFERROR(INDEX($A$25:$A$118, MATCH(1,(EL25:EL118=SMALL(EL25:EL118,1))*(COUNTIF(EL3, $A$25:$A$118)=0),0)), "")} | EM4: {=IFERROR(INDEX($A$25:$A$118, MATCH(1,(EM25:EM118=SMALL(EM25:EM118,1))*(COUNTIF(EM3, $A$25:$A$118)=0),0)), "")} | EN4: {=IFERROR(INDEX($A$25:$A$118, MATCH(1,(EN25:EN118=SMALL(EN25:EN118,1))*(COUNTIF(EN3, $A$25:$A$118)=0),0)), "")} | EO4: {=IFERROR(INDEX($A$25:$A$118, MATCH(1,(EO25:EO118=SMALL(EO25:EO118,1))*(COUNTIF(EO3, $A$25:$A$118)=0),0)), "")} | ... ER4: {=IFERROR(INDEX($A$25:$A$118, MATCH(1,(ER25:ER118=SMALL(ER25:ER118,1))*(COUNTIF(ER3, $A$25:$A$118)=0),0)), "")} | ES4: {=IFERROR(INDEX($A$25:$A$126, MATCH(1,(ES25:ES126=SMALL(ES25:ES126,1))*(COUNTIF(ES3, $A$25:$A$126)=0),0)), "")} | ET4: {=IFERROR(INDEX($A$25:$A$126, MATCH(1,(ET25:ET126=SMALL(ET25:ET126,1))*(COUNTIF(ET3, $A$25:$A$126)=0),0)), "")} | EU4: {=IFERROR(INDEX($A$25:$A$126, MATCH(1,(EU25:EU126=SMALL(EU25:EU126,1))*(COUNTIF(EU3, $A$25:$A$126)=0),0)), "")} | EV4: {=IFERROR(INDEX($A$25:$A$126, MATCH(1,(EV25:EV126=SMALL(EV25:EV126,1))*(COUNTIF(EV3, $A$25:$A$126)=0),0)), "")} | EW4: {=IFERROR(INDEX($A$25:$A$126, MATCH(1,(EW25:EW126=SMALL(EW25:EW126,1))*(COUNTIF(EW3, $A$25:$A$126)=0),0)), "")} | EX4: {=IFERROR(INDEX($A$25:$A$126, MATCH(1,(EX25:EX126=SMALL(EX25:EX126,1))*(COUNTIF(EX3, $A$25:$A$126)=0),0)), "")} | EY4: {=IFERROR(INDEX($A$25:$A$126, MATCH(1,(EY25:EY126=SMALL(EY25:EY126,1))*(COUNTIF(EY3, $A$25:$A$126)=0),0)), "")} | EZ4: {=IFERROR(INDEX($A$25:$A$126, MATCH(1,(EZ25:EZ126=SMALL(EZ25:EZ126,1))*(COUNTIF(EZ3, $A$25:$A$126)=0),0)), "")} | ... IJ4: {=IFERROR(INDEX($A$25:$A$126, MATCH(1,(IJ25:IJ126=SMALL(IJ25:IJ126,1))*(COUNTIF(IJ3, $A$25:$A$126)=0),0)), "")} | IK4: {=IFERROR(INDEX($A$25:$A$200, MATCH(1,(IK25:IK200=SMALL(IK25:IK200,1))*(COUNTIF(IK3, $A$25:$A$200)=0),0)), "")} -> BundleFusion | IL4: {=IFERROR(INDEX($A$25:$A$200, MATCH(1,(IL25:IL200=SMALL(IL25:IL200,1))*(COUNTIF(IL3, $A$25:$A$200)=0),0)), "")} | IM4: {=IFERROR(INDEX($A$25:$A$200, MATCH(1,(IM25:IM200=SMALL(IM25:IM200,1))*(COUNTIF(IM3, $A$25:$A$200)=0),0)), "")} | IN4: {=IFERROR(INDEX($A$25:$A$200, MATCH(1,(IN25:IN200=SMALL(IN25:IN200,1))*(COUNTIF(IN3, $A$25:$A$200)=0),0)), "")} -> RGBDTAM | IO4: {=IFERROR(INDEX($A$25:$A$200, MATCH(1,(IO25:IO200=SMALL(IO25:IO200,1))*(COUNTIF(IO3, $A$25:$A$200)=0),0)), "")} | IP4: {=IFERROR(INDEX($A$25:$A$200, MATCH(1,(IP25:IP200=SMALL(IP25:IP200,1))*(COUNTIF(IP3, $A$25:$A$200)=0),0)), "")} | IQ4: {=IFERROR(INDEX($A$25:$A$200, MATCH(1,(IQ25:IQ200=SMALL(IQ25:IQ200,1))*(COUNTIF(IQ3, $A$25:$A$200)=0),0)), "")} | IR4: {=IFERROR(INDEX($A$25:$A$200, MATCH(1,(IR25:IR200=SMALL(IR25:IR200,1))*(COUNTIF(IR3, $A$25:$A$200)=0),0)), "")} | ... AGQ4: {=IFERROR(INDEX($A$25:$A$200, MATCH(1,(AGQ25:AGQ200=SMALL(AGQ25:AGQ200,1))*(COUNTIF(AGQ3, $A$25:$A$200)=0),0)), "")}
B5: {=IFERROR(INDEX($A$25:$A$118, MATCH(1,(B25:B118=SMALL(B25:B118,1))*(COUNTIF(B3:B4, $A$25:$A$118)=0),0)), "")} | C5: {=IFERROR(INDEX($A$25:$A$118, MATCH(1,(C25:C118=SMALL(C25:C118,1))*(COUNTIF(C3:C4, $A$25:$A$118)=0),0)), "")} | D5: {=IFERROR(INDEX($A$25:$A$118, MATCH(1,(D25:D118=SMALL(D25:D118,1))*(COUNTIF(D3:D4, $A$25:$A$118)=0),0)), "")} | E5: {=IFERROR(INDEX($A$25:$A$118, MATCH(1,(E25:E118=SMALL(E25:E118,1))*(COUNTIF(E3:E4, $A$25:$A$118)=0),0)), "")} | F5: {=IFERROR(INDEX($A$25:$A$118, MATCH(1,(F25:F118=SMALL(F25:F118,1))*(COUNTIF(F3:F4, $A$25:$A$118)=0),0)), "")} | G5: {=IFERROR(INDEX($A$25:$A$118, MATCH(1,(G25:G118=SMALL(G25:G118,1))*(COUNTIF(G3:G4, $A$25:$A$118)=0),0)), "")} | H5: {=IFERROR(INDEX($A$25:$A$118, MATCH(1,(H25:H118=SMALL(H25:H118,1))*(COUNTIF(H3:H4, $A$25:$A$118)=0),0)), "")} | I5: {=IFERROR(INDEX($A$25:$A$118, MATCH(1,(I25:I118=SMALL(I25:I118,1))*(COUNTIF(I3:I4, $A$25:$A$118)=0),0)), "")} | ... DZ5: {=IFERROR(INDEX($A$25:$A$118, MATCH(1,(DZ25:DZ118=SMALL(DZ25:DZ118,1))*(COUNTIF(DZ3:DZ4, $A$25:$A$118)=0),0)), "")} | EC5: {=IFERROR(INDEX($A$25:$A$118, MATCH(1,(EC25:EC118=SMALL(EC25:EC118,1))*(COUNTIF(EC3:EC4, $A$25:$A$118)=0),0)), "")} | EF5: {=IFERROR(INDEX($A$25:$A$118, MATCH(1,(EF25:EF118=SMALL(EF25:EF118,1))*(COUNTIF(EF3:EF4, $A$25:$A$118)=0),0)), "")} | EH5: {=IFERROR(INDEX($A$25:$A$118, MATCH(1,(EH25:EH118=SMALL(EH25:EH118,1))*(COUNTIF(EH3:EH4, $A$25:$A$118)=0),0)), "")} | EI5: {=IFERROR(INDEX($A$25:$A$118, MATCH(1,(EI25:EI118=SMALL(EI25:EI118,1))*(COUNTIF(EI3:EI4, $A$25:$A$118)=0),0)), "")} | EJ5: {=IFERROR(INDEX($A$25:$A$118, MATCH(1,(EJ25:EJ118=SMALL(EJ25:EJ118,1))*(COUNTIF(EJ3:EJ4, $A$25:$A$118)=0),0)), "")} | EK5: {=IFERROR(INDEX($A$25:$A$118, MATCH(1,(EK25:EK118=SMALL(EK25:EK118,1))*(COUNTIF(EK3:EK4, $A$25:$A$118)=0),0)), "")} | EL5: {=IFERROR(INDEX($A$25:$A$118, MATCH(1,(EL25:EL118=SMALL(EL25:EL118,1))*(COUNTIF(EL3:EL4, $A$25:$A$118)=0),0)), "")} | EM5: {=IFERROR(INDEX($A$25:$A$118, MATCH(1,(EM25:EM118=SMALL(EM25:EM118,1))*(COUNTIF(EM3:EM4, $A$25:$A$118)=0),0)), "")} | EN5: {=IFERROR(INDEX($A$25:$A$118, MATCH(1,(EN25:EN118=SMALL(EN25:EN118,1))*(COUNTIF(EN3:EN4, $A$25:$A$118)=0),0)), "")} | EO5: {=IFERROR(INDEX($A$25:$A$118, MATCH(1,(EO25:EO118=SMALL(EO25:EO118,1))*(COUNTIF(EO3:EO4, $A$25:$A$118)=0),0)), "")} | ... ER5: {=IFERROR(INDEX($A$25:$A$118, MATCH(1,(ER25:ER118=SMALL(ER25:ER118,1))*(COUNTIF(ER3:ER4, $A$25:$A$118)=0),0)), "")} | ES5: {=IFERROR(INDEX($A$25:$A$126, MATCH(1,(ES25:ES126=SMALL(ES25:ES126,1))*(COUNTIF(ES3:ES4, $A$25:$A$126)=0),0)), "")} | ET5: {=IFERROR(INDEX($A$25:$A$126, MATCH(1,(ET25:ET126=SMALL(ET25:ET126,1))*(COUNTIF(ET3:ET4, $A$25:$A$126)=0),0)), "")} | EU5: {=IFERROR(INDEX($A$25:$A$126, MATCH(1,(EU25:EU126=SMALL(EU25:EU126,1))*(COUNTIF(EU3:EU4, $A$25:$A$126)=0),0)), "")} | EV5: {=IFERROR(INDEX($A$25:$A$126, MATCH(1,(EV25:EV126=SMALL(EV25:EV126,1))*(COUNTIF(EV3:EV4, $A$25:$A$126)=0),0)), "")} | EW5: {=IFERROR(INDEX($A$25:$A$126, MATCH(1,(EW25:EW126=SMALL(EW25:EW126,1))*(COUNTIF(EW3:EW4, $A$25:$A$126)=0),0)), "")} | EX5: {=IFERROR(INDEX($A$25:$A$126, MATCH(1,(EX25:EX126=SMALL(EX25:EX126,1))*(COUNTIF(EX3:EX4, $A$25:$A$126)=0),0)), "")} | EY5: {=IFERROR(INDEX($A$25:$A$126, MATCH(1,(EY25:EY126=SMALL(EY25:EY126,1))*(COUNTIF(EY3:EY4, $A$25:$A$126)=0),0)), "")} | EZ5: {=IFERROR(INDEX($A$25:$A$126, MATCH(1,(EZ25:EZ126=SMALL(EZ25:EZ126,1))*(COUNTIF(EZ3:EZ4, $A$25:$A$126)=0),0)), "")} | ... IJ5: {=IFERROR(INDEX($A$25:$A$126, MATCH(1,(IJ25:IJ126=SMALL(IJ25:IJ126,1))*(COUNTIF(IJ3:IJ4, $A$25:$A$126)=0),0)), "")} | IK5: {=IFERROR(INDEX($A$25:$A$200, MATCH(1,(IK25:IK200=SMALL(IK25:IK200,1))*(COUNTIF(IK3:IK4, $A$25:$A$200)=0),0)), "")} | IL5: {=IFERROR(INDEX($A$25:$A$200, MATCH(1,(IL25:IL200=SMALL(IL25:IL200,1))*(COUNTIF(IL3:IL4, $A$25:$A$200)=0),0)), "")} | IM5: {=IFERROR(INDEX($A$25:$A$200, MATCH(1,(IM25:IM200=SMALL(IM25:IM200,1))*(COUNTIF(IM3:IM4, $A$25:$A$200)=0),0)), "")} | IN5: {=IFERROR(INDEX($A$25:$A$200, MATCH(1,(IN25:IN200=SMALL(IN25:IN200,1))*(COUNTIF(IN3:IN4, $A$25:$A$200)=0),0)), "")} | IO5: {=IFERROR(INDEX($A$25:$A$200, MATCH(1,(IO25:IO200=SMALL(IO25:IO200,1))*(COUNTIF(IO3:IO4, $A$25:$A$200)=0),0)), "")} | IP5: {=IFERROR(INDEX($A$25:$A$200, MATCH(1,(IP25:IP200=SMALL(IP25:IP200,1))*(COUNTIF(IP3:IP4, $A$25:$A$200)=0),0)), "")} | IQ5: {=IFERROR(INDEX($A$25:$A$200, MATCH(1,(IQ25:IQ200=SMALL(IQ25:IQ200,1))*(COUNTIF(IQ3:IQ4, $A$25:$A$200)=0),0)), "")} | IR5: {=IFERROR(INDEX($A$25:$A$200, MATCH(1,(IR25:IR200=SMALL(IR25:IR200,1))*(COUNTIF(IR3:IR4, $A$25:$A$200)=0),0)), "")} | ... AGQ5: {=IFERROR(INDEX($A$25:$A$200, MATCH(1,(AGQ25:AGQ200=SMALL(AGQ25:AGQ200,1))*(COUNTIF(AGQ3:AGQ4, $A$25:$A$200)=0),0)), "")}
A6: Algoritmos com erro inferior a: | B6: {=IFERROR(IF(SMALL(B25:B118,2)<=$A$8*SMALL(B25:B118,1),IFERROR(INDEX($A$25:$A$118, MATCH(1,(B25:B118=SMALL(B25:B118,2))*(COUNTIF(B3:B5, $A$25:$A$118)=0),0)), ""),""),"")} | C6: {=IFERROR(IF(SMALL(C25:C118,2)<=$A$8*SMALL(C25:C118,1),IFERROR(INDEX($A$25:$A$118, MATCH(1,(C25:C118=SMALL(C25:C118,2))*(COUNTIF(C3:C5, $A$25:$A$118)=0),0)), ""),""),"")} | D6: {=IFERROR(IF(SMALL(D25:D118,2)<=$A$8*SMALL(D25:D118,1),IFERROR(INDEX($A$25:$A$118, MATCH(1,(D25:D118=SMALL(D25:D118,2))*(COUNTIF(D3:D5, $A$25:$A$118)=0),0)), ""),""),"")} -> OpenVINS | E6: {=IFERROR(IF(SMALL(E25:E118,2)<=$A$8*SMALL(E25:E118,1),IFERROR(INDEX($A$25:$A$118, MATCH(1,(E25:E118=SMALL(E25:E118,2))*(COUNTIF(E3:E5, $A$25:$A$118)=0),0)), ""),""),"")} -> ORB-SLAM2 | F6: {=IFERROR(IF(SMALL(F25:F118,2)<=$A$8*SMALL(F25:F118,1),IFERROR(INDEX($A$25:$A$118, MATCH(1,(F25:F118=SMALL(F25:F118,2))*(COUNTIF(F3:F5, $A$25:$A$118)=0),0)), ""),""),"")} | G6: {=IFERROR(IF(SMALL(G25:G118,2)<=$A$8*SMALL(G25:G118,1),IFERROR(INDEX($A$25:$A$118, MATCH(1,(G25:G118=SMALL(G25:G118,2))*(COUNTIF(G3:G5, $A$25:$A$118)=0),0)), ""),""),"")} | H6: {=IFERROR(IF(SMALL(H25:H118,2)<=$A$8*SMALL(H25:H118,1),IFERROR(INDEX($A$25:$A$118, MATCH(1,(H25:H118=SMALL(H25:H118,2))*(COUNTIF(H3:H5, $A$25:$A$118)=0),0)), ""),""),"")} -> ORB-SLAM3 | I6: {=IFERROR(IF(SMALL(I25:I118,2)<=$A$8*SMALL(I25:I118,1),IFERROR(INDEX($A$25:$A$118, MATCH(1,(I25:I118=SMALL(I25:I118,2))*(COUNTIF(I3:I5, $A$25:$A$118)=0),0)), ""),""),"")} -> VINS-Mono | ... DZ6: {=IFERROR(IF(SMALL(DZ25:DZ118,2)<=$A$8*SMALL(DZ25:DZ118,1),IFERROR(INDEX($A$25:$A$118, MATCH(1,(DZ25:DZ118=SMALL(DZ25:DZ118,2))*(COUNTIF(DZ3:DZ5, $A$25:$A$118)=0),0)), ""),""),"")} -> LIO-SAM | EC6: {=IFERROR(IF(SMALL(EC25:EC118,2)<=$A$8*SMALL(EC25:EC118,1),IFERROR(INDEX($A$25:$A$118, MATCH(1,(EC25:EC118=SMALL(EC25:EC118,2))*(COUNTIF(EC3:EC5, $A$25:$A$118)=0),0)), ""),""),"")} -> Basalt | EF6: {=IFERROR(IF(SMALL(EF25:EF118,2)<=$A$8*SMALL(EF25:EF118,1),IFERROR(INDEX($A$25:$A$118, MATCH(1,(EF25:EF118=SMALL(EF25:EF118,2))*(COUNTIF(EF3:EF5, $A$25:$A$118)=0),0)), ""),""),"")} -> LeGO-LOAM | EH6: {=IFERROR(IF(SMALL(EH25:EH118,2)<=$A$8*SMALL(EH25:EH118,1),IFERROR(INDEX($A$25:$A$118, MATCH(1,(EH25:EH118=SMALL(EH25:EH118,2))*(COUNTIF(EH3:EH5, $A$25:$A$118)=0),0)), ""),""),"")} | EI6: {=IFERROR(IF(SMALL(EI25:EI118,2)<=$A$8*SMALL(EI25:EI118,1),IFERROR(INDEX($A$25:$A$118, MATCH(1,(EI25:EI118=SMALL(EI25:EI118,2))*(COUNTIF(EI3:EI5, $A$25:$A$118)=0),0)), ""),""),"")} -> RTAB. Stereo. ORB2 | EJ6: {=IFERROR(IF(SMALL(EJ25:EJ118,2)<=$A$8*SMALL(EJ25:EJ118,1),IFERROR(INDEX($A$25:$A$118, MATCH(1,(EJ25:EJ118=SMALL(EJ25:EJ118,2))*(COUNTIF(EJ3:EJ5, $A$25:$A$118)=0),0)), ""),""),"")} | EK6: {=IFERROR(IF(SMALL(EK25:EK118,2)<=$A$8*SMALL(EK25:EK118,1),IFERROR(INDEX($A$25:$A$118, MATCH(1,(EK25:EK118=SMALL(EK25:EK118,2))*(COUNTIF(EK3:EK5, $A$25:$A$118)=0),0)), ""),""),"")} -> ORB-SLAM2 | EL6: {=IFERROR(IF(SMALL(EL25:EL118,2)<=$A$8*SMALL(EL25:EL118,1),IFERROR(INDEX($A$25:$A$118, MATCH(1,(EL25:EL118=SMALL(EL25:EL118,2))*(COUNTIF(EL3:EL5, $A$25:$A$118)=0),0)), ""),""),"")} -> ORB-SLAM2 | EM6: {=IFERROR(IF(SMALL(EM25:EM118,2)<=$A$8*SMALL(EM25:EM118,1),IFERROR(INDEX($A$25:$A$118, MATCH(1,(EM25:EM118=SMALL(EM25:EM118,2))*(COUNTIF(EM3:EM5, $A$25:$A$118)=0),0)), ""),""),"")} -> DV-LOAM | EN6: {=IFERROR(IF(SMALL(EN25:EN118,2)<=$A$8*SMALL(EN25:EN118,1),IFERROR(INDEX($A$25:$A$118, MATCH(1,(EN25:EN118=SMALL(EN25:EN118,2))*(COUNTIF(EN3:EN5, $A$25:$A$118)=0),0)), ""),""),"")} -> RTAB. Stereo. F2M | EO6: {=IFERROR(IF(SMALL(EO25:EO118,2)<=$A$8*SMALL(EO25:EO118,1),IFERROR(INDEX($A$25:$A$118, MATCH(1,(EO25:EO118=SMALL(EO25:EO118,2))*(COUNTIF(EO3:EO5, $A$25:$A$118)=0),0)), ""),""),"")} -> ORB-SLAM2 | ... ER6: {=IFERROR(IF(SMALL(ER25:ER118,2)<=$A$8*SMALL(ER25:ER118,1),IFERROR(INDEX($A$25:$A$118, MATCH(1,(ER25:ER118=SMALL(ER25:ER118,2))*(COUNTIF(ER3:ER5, $A$25:$A$118)=0),0)), ""),""),"")} -> DV-LOAM | ES6: {=IFERROR(IF(SMALL(ES25:ES126,2)<=$A$8*SMALL(ES25:ES126,1),IFERROR(INDEX($A$25:$A$126, MATCH(1,(ES25:ES126=SMALL(ES25:ES126,2))*(COUNTIF(ES3:ES5, $A$25:$A$126)=0),0)), ""),""),"")} -> RTAB. Stereo. ORB2 | ET6: {=IFERROR(IF(SMALL(ET25:ET126,2)<=$A$8*SMALL(ET25:ET126,1),IFERROR(INDEX($A$25:$A$126, MATCH(1,(ET25:ET126=SMALL(ET25:ET126,2))*(COUNTIF(ET3:ET5, $A$25:$A$126)=0),0)), ""),""),"")} -> OKVIS | EU6: {=IFERROR(IF(SMALL(EU25:EU126,2)<=$A$8*SMALL(EU25:EU126,1),IFERROR(INDEX($A$25:$A$126, MATCH(1,(EU25:EU126=SMALL(EU25:EU126,2))*(COUNTIF(EU3:EU5, $A$25:$A$126)=0),0)), ""),""),"")} -> OKVIS | EV6: {=IFERROR(IF(SMALL(EV25:EV126,2)<=$A$8*SMALL(EV25:EV126,1),IFERROR(INDEX($A$25:$A$126, MATCH(1,(EV25:EV126=SMALL(EV25:EV126,2))*(COUNTIF(EV3:EV5, $A$25:$A$126)=0),0)), ""),""),"")} -> VINS-Mono | EW6: {=IFERROR(IF(SMALL(EW25:EW126,2)<=$A$8*SMALL(EW25:EW126,1),IFERROR(INDEX($A$25:$A$126, MATCH(1,(EW25:EW126=SMALL(EW25:EW126,2))*(COUNTIF(EW3:EW5, $A$25:$A$126)=0),0)), ""),""),"")} -> OKVIS | EX6: {=IFERROR(IF(SMALL(EX25:EX126,2)<=$A$8*SMALL(EX25:EX126,1),IFERROR(INDEX($A$25:$A$126, MATCH(1,(EX25:EX126=SMALL(EX25:EX126,2))*(COUNTIF(EX3:EX5, $A$25:$A$126)=0),0)), ""),""),"")} | EY6: {=IFERROR(IF(SMALL(EY25:EY126,2)<=$A$8*SMALL(EY25:EY126,1),IFERROR(INDEX($A$25:$A$126, MATCH(1,(EY25:EY126=SMALL(EY25:EY126,2))*(COUNTIF(EY3:EY5, $A$25:$A$126)=0),0)), ""),""),"")} | EZ6: {=IFERROR(IF(SMALL(EZ25:EZ126,2)<=$A$8*SMALL(EZ25:EZ126,1),IFERROR(INDEX($A$25:$A$126, MATCH(1,(EZ25:EZ126=SMALL(EZ25:EZ126,2))*(COUNTIF(EZ3:EZ5, $A$25:$A$126)=0),0)), ""),""),"")} | ... IJ6: {=IFERROR(IF(SMALL(IJ25:IJ126,2)<=$A$8*SMALL(IJ25:IJ126,1),IFERROR(INDEX($A$25:$A$126, MATCH(1,(IJ25:IJ126=SMALL(IJ25:IJ126,2))*(COUNTIF(IJ3:IJ5, $A$25:$A$126)=0),0)), ""),""),"")} -> DynaSLAM | IK6: {=IFERROR(IF(SMALL(IK25:IK200,2)<=$A$8*SMALL(IK25:IK200,1),IFERROR(INDEX($A$25:$A$200, MATCH(1,(IK25:IK200=SMALL(IK25:IK200,2))*(COUNTIF(IK3:IK5, $A$25:$A$200)=0),0)), ""),""),"")} | IL6: {=IFERROR(IF(SMALL(IL25:IL200,2)<=$A$8*SMALL(IL25:IL200,1),IFERROR(INDEX($A$25:$A$200, MATCH(1,(IL25:IL200=SMALL(IL25:IL200,2))*(COUNTIF(IL3:IL5, $A$25:$A$200)=0),0)), ""),""),"")} | IM6: {=IFERROR(IF(SMALL(IM25:IM200,2)<=$A$8*SMALL(IM25:IM200,1),IFERROR(INDEX($A$25:$A$200, MATCH(1,(IM25:IM200=SMALL(IM25:IM200,2))*(COUNTIF(IM3:IM5, $A$25:$A$200)=0),0)), ""),""),"")} -> DVO-SLAM | IN6: {=IFERROR(IF(SMALL(IN25:IN200,2)<=$A$8*SMALL(IN25:IN200,1),IFERROR(INDEX($A$25:$A$200, MATCH(1,(IN25:IN200=SMALL(IN25:IN200,2))*(COUNTIF(IN3:IN5, $A$25:$A$200)=0),0)), ""),""),"")} | IO6: {=IFERROR(IF(SMALL(IO25:IO200,2)<=$A$8*SMALL(IO25:IO200,1),IFERROR(INDEX($A$25:$A$200, MATCH(1,(IO25:IO200=SMALL(IO25:IO200,2))*(COUNTIF(IO3:IO5, $A$25:$A$200)=0),0)), ""),""),"")} | IP6: {=IFERROR(IF(SMALL(IP25:IP200,2)<=$A$8*SMALL(IP25:IP200,1),IFERROR(INDEX($A$25:$A$200, MATCH(1,(IP25:IP200=SMALL(IP25:IP200,2))*(COUNTIF(IP3:IP5, $A$25:$A$200)=0),0)), ""),""),"")} -> Plane-Edge-SLAM | IQ6: {=IFERROR(IF(SMALL(IQ25:IQ200,2)<=$A$8*SMALL(IQ25:IQ200,1),IFERROR(INDEX($A$25:$A$200, MATCH(1,(IQ25:IQ200=SMALL(IQ25:IQ200,2))*(COUNTIF(IQ3:IQ5, $A$25:$A$200)=0),0)), ""),""),"")} | IR6: {=IFERROR(IF(SMALL(IR25:IR200,2)<=$A$8*SMALL(IR25:IR200,1),IFERROR(INDEX($A$25:$A$200, MATCH(1,(IR25:IR200=SMALL(IR25:IR200,2))*(COUNTIF(IR3:IR5, $A$25:$A$200)=0),0)), ""),""),"")} | ... AGQ6: {=IFERROR(IF(SMALL(AGQ25:AGQ200,2)<=$A$8*SMALL(AGQ25:AGQ200,1),IFERROR(INDEX($A$25:$A$200, MATCH(1,(AGQ25:AGQ200=SMALL(AGQ25:AGQ200,2))*(COUNTIF(AGQ3:AGQ5, $A$25:$A$200)=0),0)), ""),""),"")}
B7: {=IFERROR(IF(SMALL(B25:B118,2)<=$A$8*SMALL(B25:B118,1),IFERROR(INDEX($A$25:$A$118, MATCH(1,(B25:B118=SMALL(B25:B118,2))*(COUNTIF(B3:B6, $A$25:$A$118)=0),0)), ""),""),"")} | C7: {=IFERROR(IF(SMALL(C25:C118,2)<=$A$8*SMALL(C25:C118,1),IFERROR(INDEX($A$25:$A$118, MATCH(1,(C25:C118=SMALL(C25:C118,2))*(COUNTIF(C3:C6, $A$25:$A$118)=0),0)), ""),""),"")} | D7: {=IFERROR(IF(SMALL(D25:D118,2)<=$A$8*SMALL(D25:D118,1),IFERROR(INDEX($A$25:$A$118, MATCH(1,(D25:D118=SMALL(D25:D118,2))*(COUNTIF(D3:D6, $A$25:$A$118)=0),0)), ""),""),"")} | E7: {=IFERROR(IF(SMALL(E25:E118,2)<=$A$8*SMALL(E25:E118,1),IFERROR(INDEX($A$25:$A$118, MATCH(1,(E25:E118=SMALL(E25:E118,2))*(COUNTIF(E3:E6, $A$25:$A$118)=0),0)), ""),""),"")} | F7: {=IFERROR(IF(SMALL(F25:F118,2)<=$A$8*SMALL(F25:F118,1),IFERROR(INDEX($A$25:$A$118, MATCH(1,(F25:F118=SMALL(F25:F118,2))*(COUNTIF(F3:F6, $A$25:$A$118)=0),0)), ""),""),"")} | G7: {=IFERROR(IF(SMALL(G25:G118,2)<=$A$8*SMALL(G25:G118,1),IFERROR(INDEX($A$25:$A$118, MATCH(1,(G25:G118=SMALL(G25:G118,2))*(COUNTIF(G3:G6, $A$25:$A$118)=0),0)), ""),""),"")} | H7: {=IFERROR(IF(SMALL(H25:H118,2)<=$A$8*SMALL(H25:H118,1),IFERROR(INDEX($A$25:$A$118, MATCH(1,(H25:H118=SMALL(H25:H118,2))*(COUNTIF(H3:H6, $A$25:$A$118)=0),0)), ""),""),"")} | I7: {=IFERROR(IF(SMALL(I25:I118,2)<=$A$8*SMALL(I25:I118,1),IFERROR(INDEX($A$25:$A$118, MATCH(1,(I25:I118=SMALL(I25:I118,2))*(COUNTIF(I3:I6, $A$25:$A$118)=0),0)), ""),""),"")} | ... DZ7: {=IFERROR(IF(SMALL(DZ25:DZ118,2)<=$A$8*SMALL(DZ25:DZ118,1),IFERROR(INDEX($A$25:$A$118, MATCH(1,(DZ25:DZ118=SMALL(DZ25:DZ118,2))*(COUNTIF(DZ3:DZ6, $A$25:$A$118)=0),0)), ""),""),"")} | EC7: {=IFERROR(IF(SMALL(EC25:EC118,2)<=$A$8*SMALL(EC25:EC118,1),IFERROR(INDEX($A$25:$A$118, MATCH(1,(EC25:EC118=SMALL(EC25:EC118,2))*(COUNTIF(EC3:EC6, $A$25:$A$118)=0),0)), ""),""),"")} | EF7: {=IFERROR(IF(SMALL(EF25:EF118,2)<=$A$8*SMALL(EF25:EF118,1),IFERROR(INDEX($A$25:$A$118, MATCH(1,(EF25:EF118=SMALL(EF25:EF118,2))*(COUNTIF(EF3:EF6, $A$25:$A$118)=0),0)), ""),""),"")} | EH7: {=IFERROR(IF(SMALL(EH25:EH118,2)<=$A$8*SMALL(EH25:EH118,1),IFERROR(INDEX($A$25:$A$118, MATCH(1,(EH25:EH118=SMALL(EH25:EH118,2))*(COUNTIF(EH3:EH6, $A$25:$A$118)=0),0)), ""),""),"")} | EI7: {=IFERROR(IF(SMALL(EI25:EI118,2)<=$A$8*SMALL(EI25:EI118,1),IFERROR(INDEX($A$25:$A$118, MATCH(1,(EI25:EI118=SMALL(EI25:EI118,2))*(COUNTIF(EI3:EI6, $A$25:$A$118)=0),0)), ""),""),"")} | EJ7: {=IFERROR(IF(SMALL(EJ25:EJ118,2)<=$A$8*SMALL(EJ25:EJ118,1),IFERROR(INDEX($A$25:$A$118, MATCH(1,(EJ25:EJ118=SMALL(EJ25:EJ118,2))*(COUNTIF(EJ3:EJ6, $A$25:$A$118)=0),0)), ""),""),"")} | EK7: {=IFERROR(IF(SMALL(EK25:EK118,2)<=$A$8*SMALL(EK25:EK118,1),IFERROR(INDEX($A$25:$A$118, MATCH(1,(EK25:EK118=SMALL(EK25:EK118,2))*(COUNTIF(EK3:EK6, $A$25:$A$118)=0),0)), ""),""),"")} | EL7: {=IFERROR(IF(SMALL(EL25:EL118,2)<=$A$8*SMALL(EL25:EL118,1),IFERROR(INDEX($A$25:$A$118, MATCH(1,(EL25:EL118=SMALL(EL25:EL118,2))*(COUNTIF(EL3:EL6, $A$25:$A$118)=0),0)), ""),""),"")} | EM7: {=IFERROR(IF(SMALL(EM25:EM118,2)<=$A$8*SMALL(EM25:EM118,1),IFERROR(INDEX($A$25:$A$118, MATCH(1,(EM25:EM118=SMALL(EM25:EM118,2))*(COUNTIF(EM3:EM6, $A$25:$A$118)=0),0)), ""),""),"")} | EN7: {=IFERROR(IF(SMALL(EN25:EN118,2)<=$A$8*SMALL(EN25:EN118,1),IFERROR(INDEX($A$25:$A$118, MATCH(1,(EN25:EN118=SMALL(EN25:EN118,2))*(COUNTIF(EN3:EN6, $A$25:$A$118)=0),0)), ""),""),"")} | EO7: {=IFERROR(IF(SMALL(EO25:EO118,2)<=$A$8*SMALL(EO25:EO118,1),IFERROR(INDEX($A$25:$A$118, MATCH(1,(EO25:EO118=SMALL(EO25:EO118,2))*(COUNTIF(EO3:EO6, $A$25:$A$118)=0),0)), ""),""),"")} | ... ER7: {=IFERROR(IF(SMALL(ER25:ER118,2)<=$A$8*SMALL(ER25:ER118,1),IFERROR(INDEX($A$25:$A$118, MATCH(1,(ER25:ER118=SMALL(ER25:ER118,2))*(COUNTIF(ER3:ER6, $A$25:$A$118)=0),0)), ""),""),"")} | ES7: {=IFERROR(IF(SMALL(ES25:ES126,2)<=$A$8*SMALL(ES25:ES126,1),IFERROR(INDEX($A$25:$A$126, MATCH(1,(ES25:ES126=SMALL(ES25:ES126,2))*(COUNTIF(ES3:ES6, $A$25:$A$126)=0),0)), ""),""),"")} | ET7: {=IFERROR(IF(SMALL(ET25:ET126,2)<=$A$8*SMALL(ET25:ET126,1),IFERROR(INDEX($A$25:$A$126, MATCH(1,(ET25:ET126=SMALL(ET25:ET126,2))*(COUNTIF(ET3:ET6, $A$25:$A$126)=0),0)), ""),""),"")} | EU7: {=IFERROR(IF(SMALL(EU25:EU126,2)<=$A$8*SMALL(EU25:EU126,1),IFERROR(INDEX($A$25:$A$126, MATCH(1,(EU25:EU126=SMALL(EU25:EU126,2))*(COUNTIF(EU3:EU6, $A$25:$A$126)=0),0)), ""),""),"")} | EV7: {=IFERROR(IF(SMALL(EV25:EV126,2)<=$A$8*SMALL(EV25:EV126,1),IFERROR(INDEX($A$25:$A$126, MATCH(1,(EV25:EV126=SMALL(EV25:EV126,2))*(COUNTIF(EV3:EV6, $A$25:$A$126)=0),0)), ""),""),"")} | EW7: {=IFERROR(IF(SMALL(EW25:EW126,2)<=$A$8*SMALL(EW25:EW126,1),IFERROR(INDEX($A$25:$A$126, MATCH(1,(EW25:EW126=SMALL(EW25:EW126,2))*(COUNTIF(EW3:EW6, $A$25:$A$126)=0),0)), ""),""),"")} | EX7: {=IFERROR(IF(SMALL(EX25:EX126,2)<=$A$8*SMALL(EX25:EX126,1),IFERROR(INDEX($A$25:$A$126, MATCH(1,(EX25:EX126=SMALL(EX25:EX126,2))*(COUNTIF(EX3:EX6, $A$25:$A$126)=0),0)), ""),""),"")} | EY7: {=IFERROR(IF(SMALL(EY25:EY126,2)<=$A$8*SMALL(EY25:EY126,1),IFERROR(INDEX($A$25:$A$126, MATCH(1,(EY25:EY126=SMALL(EY25:EY126,2))*(COUNTIF(EY3:EY6, $A$25:$A$126)=0),0)), ""),""),"")} | EZ7: {=IFERROR(IF(SMALL(EZ25:EZ126,2)<=$A$8*SMALL(EZ25:EZ126,1),IFERROR(INDEX($A$25:$A$126, MATCH(1,(EZ25:EZ126=SMALL(EZ25:EZ126,2))*(COUNTIF(EZ3:EZ6, $A$25:$A$126)=0),0)), ""),""),"")} | ... IJ7: {=IFERROR(IF(SMALL(IJ25:IJ126,2)<=$A$8*SMALL(IJ25:IJ126,1),IFERROR(INDEX($A$25:$A$126, MATCH(1,(IJ25:IJ126=SMALL(IJ25:IJ126,2))*(COUNTIF(IJ3:IJ6, $A$25:$A$126)=0),0)), ""),""),"")} | IK7: {=IFERROR(IF(SMALL(IK25:IK200,2)<=$A$8*SMALL(IK25:IK200,1),IFERROR(INDEX($A$25:$A$200, MATCH(1,(IK25:IK200=SMALL(IK25:IK200,2))*(COUNTIF(IK3:IK6, $A$25:$A$200)=0),0)), ""),""),"")} | IL7: {=IFERROR(IF(SMALL(IL25:IL200,2)<=$A$8*SMALL(IL25:IL200,1),IFERROR(INDEX($A$25:$A$200, MATCH(1,(IL25:IL200=SMALL(IL25:IL200,2))*(COUNTIF(IL3:IL6, $A$25:$A$200)=0),0)), ""),""),"")} | IM7: {=IFERROR(IF(SMALL(IM25:IM200,2)<=$A$8*SMALL(IM25:IM200,1),IFERROR(INDEX($A$25:$A$200, MATCH(1,(IM25:IM200=SMALL(IM25:IM200,2))*(COUNTIF(IM3:IM6, $A$25:$A$200)=0),0)), ""),""),"")} | IN7: {=IFERROR(IF(SMALL(IN25:IN200,2)<=$A$8*SMALL(IN25:IN200,1),IFERROR(INDEX($A$25:$A$200, MATCH(1,(IN25:IN200=SMALL(IN25:IN200,2))*(COUNTIF(IN3:IN6, $A$25:$A$200)=0),0)), ""),""),"")} | IO7: {=IFERROR(IF(SMALL(IO25:IO200,2)<=$A$8*SMALL(IO25:IO200,1),IFERROR(INDEX($A$25:$A$200, MATCH(1,(IO25:IO200=SMALL(IO25:IO200,2))*(COUNTIF(IO3:IO6, $A$25:$A$200)=0),0)), ""),""),"")} | IP7: {=IFERROR(IF(SMALL(IP25:IP200,2)<=$A$8*SMALL(IP25:IP200,1),IFERROR(INDEX($A$25:$A$200, MATCH(1,(IP25:IP200=SMALL(IP25:IP200,2))*(COUNTIF(IP3:IP6, $A$25:$A$200)=0),0)), ""),""),"")} | IQ7: {=IFERROR(IF(SMALL(IQ25:IQ200,2)<=$A$8*SMALL(IQ25:IQ200,1),IFERROR(INDEX($A$25:$A$200, MATCH(1,(IQ25:IQ200=SMALL(IQ25:IQ200,2))*(COUNTIF(IQ3:IQ6, $A$25:$A$200)=0),0)), ""),""),"")} | IR7: {=IFERROR(IF(SMALL(IR25:IR200,2)<=$A$8*SMALL(IR25:IR200,1),IFERROR(INDEX($A$25:$A$200, MATCH(1,(IR25:IR200=SMALL(IR25:IR200,2))*(COUNTIF(IR3:IR6, $A$25:$A$200)=0),0)), ""),""),"")} | ... AGQ7: {=IFERROR(IF(SMALL(AGQ25:AGQ200,2)<=$A$8*SMALL(AGQ25:AGQ200,1),IFERROR(INDEX($A$25:$A$200, MATCH(1,(AGQ25:AGQ200=SMALL(AGQ25:AGQ200,2))*(COUNTIF(AGQ3:AGQ6, $A$25:$A$200)=0),0)), ""),""),"")}
A8: ='(old)OtherMetrics'!D21 -> 1.25 | B8: {=IFERROR(IF(SMALL(B25:B118,3)<=$A$8*SMALL(B25:B118,1),IFERROR(INDEX($A$25:$A$118, MATCH(1,(B25:B118=SMALL(B25:B118,3))*(COUNTIF(B6:B7, $A$25:$A$118)=0),0)), ""),""),"")} | C8: {=IFERROR(IF(SMALL(C25:C118,3)<=$A$8*SMALL(C25:C118,1),IFERROR(INDEX($A$25:$A$118, MATCH(1,(C25:C118=SMALL(C25:C118,3))*(COUNTIF(C6:C7, $A$25:$A$118)=0),0)), ""),""),"")} | D8: {=IFERROR(IF(SMALL(D25:D118,3)<=$A$8*SMALL(D25:D118,1),IFERROR(INDEX($A$25:$A$118, MATCH(1,(D25:D118=SMALL(D25:D118,3))*(COUNTIF(D6:D7, $A$25:$A$118)=0),0)), ""),""),"")} -> Kimera | E8: {=IFERROR(IF(SMALL(E25:E118,3)<=$A$8*SMALL(E25:E118,1),IFERROR(INDEX($A$25:$A$118, MATCH(1,(E25:E118=SMALL(E25:E118,3))*(COUNTIF(E6:E7, $A$25:$A$118)=0),0)), ""),""),"")} -> OpenVSLAM | F8: {=IFERROR(IF(SMALL(F25:F118,3)<=$A$8*SMALL(F25:F118,1),IFERROR(INDEX($A$25:$A$118, MATCH(1,(F25:F118=SMALL(F25:F118,3))*(COUNTIF(F6:F7, $A$25:$A$118)=0),0)), ""),""),"")} | G8: {=IFERROR(IF(SMALL(G25:G118,3)<=$A$8*SMALL(G25:G118,1),IFERROR(INDEX($A$25:$A$118, MATCH(1,(G25:G118=SMALL(G25:G118,3))*(COUNTIF(G6:G7, $A$25:$A$118)=0),0)), ""),""),"")} -> ORB-SLAM2 | H8: {=IFERROR(IF(SMALL(H25:H118,3)<=$A$8*SMALL(H25:H118,1),IFERROR(INDEX($A$25:$A$118, MATCH(1,(H25:H118=SMALL(H25:H118,3))*(COUNTIF(H6:H7, $A$25:$A$118)=0),0)), ""),""),"")} | I8: {=IFERROR(IF(SMALL(I25:I118,3)<=$A$8*SMALL(I25:I118,1),IFERROR(INDEX($A$25:$A$118, MATCH(1,(I25:I118=SMALL(I25:I118,3))*(COUNTIF(I6:I7, $A$25:$A$118)=0),0)), ""),""),"")} | ... DZ8: {=IFERROR(IF(SMALL(DZ25:DZ118,3)<=$A$8*SMALL(DZ25:DZ118,1),IFERROR(INDEX($A$25:$A$118, MATCH(1,(DZ25:DZ118=SMALL(DZ25:DZ118,3))*(COUNTIF(DZ6:DZ7, $A$25:$A$118)=0),0)), ""),""),"")} | EC8: {=IFERROR(IF(SMALL(EC25:EC118,3)<=$A$8*SMALL(EC25:EC118,1),IFERROR(INDEX($A$25:$A$118, MATCH(1,(EC25:EC118=SMALL(EC25:EC118,3))*(COUNTIF(EC6:EC7, $A$25:$A$118)=0),0)), ""),""),"")} -> HDL_Graph_SLAM | EF8: {=IFERROR(IF(SMALL(EF25:EF118,3)<=$A$8*SMALL(EF25:EF118,1),IFERROR(INDEX($A$25:$A$118, MATCH(1,(EF25:EF118=SMALL(EF25:EF118,3))*(COUNTIF(EF6:EF7, $A$25:$A$118)=0),0)), ""),""),"")} -> LIO-SAM | EH8: {=IFERROR(IF(SMALL(EH25:EH118,3)<=$A$8*SMALL(EH25:EH118,1),IFERROR(INDEX($A$25:$A$118, MATCH(1,(EH25:EH118=SMALL(EH25:EH118,3))*(COUNTIF(EH6:EH7, $A$25:$A$118)=0),0)), ""),""),"")} | EI8: {=IFERROR(IF(SMALL(EI25:EI118,3)<=$A$8*SMALL(EI25:EI118,1),IFERROR(INDEX($A$25:$A$118, MATCH(1,(EI25:EI118=SMALL(EI25:EI118,3))*(COUNTIF(EI6:EI7, $A$25:$A$118)=0),0)), ""),""),"")} -> RTAB. Stereo. F2M | EJ8: {=IFERROR(IF(SMALL(EJ25:EJ118,3)<=$A$8*SMALL(EJ25:EJ118,1),IFERROR(INDEX($A$25:$A$118, MATCH(1,(EJ25:EJ118=SMALL(EJ25:EJ118,3))*(COUNTIF(EJ6:EJ7, $A$25:$A$118)=0),0)), ""),""),"")} | EK8: {=IFERROR(IF(SMALL(EK25:EK118,3)<=$A$8*SMALL(EK25:EK118,1),IFERROR(INDEX($A$25:$A$118, MATCH(1,(EK25:EK118=SMALL(EK25:EK118,3))*(COUNTIF(EK6:EK7, $A$25:$A$118)=0),0)), ""),""),"")} -> DV-LOAM | EL8: {=IFERROR(IF(SMALL(EL25:EL118,3)<=$A$8*SMALL(EL25:EL118,1),IFERROR(INDEX($A$25:$A$118, MATCH(1,(EL25:EL118=SMALL(EL25:EL118,3))*(COUNTIF(EL6:EL7, $A$25:$A$118)=0),0)), ""),""),"")} -> RTAB. Stereo. F2M | EM8: {=IFERROR(IF(SMALL(EM25:EM118,3)<=$A$8*SMALL(EM25:EM118,1),IFERROR(INDEX($A$25:$A$118, MATCH(1,(EM25:EM118=SMALL(EM25:EM118,3))*(COUNTIF(EM6:EM7, $A$25:$A$118)=0),0)), ""),""),"")} | EN8: {=IFERROR(IF(SMALL(EN25:EN118,3)<=$A$8*SMALL(EN25:EN118,1),IFERROR(INDEX($A$25:$A$118, MATCH(1,(EN25:EN118=SMALL(EN25:EN118,3))*(COUNTIF(EN6:EN7, $A$25:$A$118)=0),0)), ""),""),"")} -> ORB-SLAM2 | EO8: {=IFERROR(IF(SMALL(EO25:EO118,3)<=$A$8*SMALL(EO25:EO118,1),IFERROR(INDEX($A$25:$A$118, MATCH(1,(EO25:EO118=SMALL(EO25:EO118,3))*(COUNTIF(EO6:EO7, $A$25:$A$118)=0),0)), ""),""),"")} -> RTAB. Stereo. F2M | ... ER8: {=IFERROR(IF(SMALL(ER25:ER118,3)<=$A$8*SMALL(ER25:ER118,1),IFERROR(INDEX($A$25:$A$118, MATCH(1,(ER25:ER118=SMALL(ER25:ER118,3))*(COUNTIF(ER6:ER7, $A$25:$A$118)=0),0)), ""),""),"")} -> LOAM | ES8: {=IFERROR(IF(SMALL(ES25:ES126,3)<=$A$8*SMALL(ES25:ES126,1),IFERROR(INDEX($A$25:$A$126, MATCH(1,(ES25:ES126=SMALL(ES25:ES126,3))*(COUNTIF(ES6:ES7, $A$25:$A$126)=0),0)), ""),""),"")} -> ORB-SLAM2 | ET8: {=IFERROR(IF(SMALL(ET25:ET126,3)<=$A$8*SMALL(ET25:ET126,1),IFERROR(INDEX($A$25:$A$126, MATCH(1,(ET25:ET126=SMALL(ET25:ET126,3))*(COUNTIF(ET6:ET7, $A$25:$A$126)=0),0)), ""),""),"")} | EU8: {=IFERROR(IF(SMALL(EU25:EU126,3)<=$A$8*SMALL(EU25:EU126,1),IFERROR(INDEX($A$25:$A$126, MATCH(1,(EU25:EU126=SMALL(EU25:EU126,3))*(COUNTIF(EU6:EU7, $A$25:$A$126)=0),0)), ""),""),"")} | EV8: {=IFERROR(IF(SMALL(EV25:EV126,3)<=$A$8*SMALL(EV25:EV126,1),IFERROR(INDEX($A$25:$A$126, MATCH(1,(EV25:EV126=SMALL(EV25:EV126,3))*(COUNTIF(EV6:EV7, $A$25:$A$126)=0),0)), ""),""),"")} | EW8: {=IFERROR(IF(SMALL(EW25:EW126,3)<=$A$8*SMALL(EW25:EW126,1),IFERROR(INDEX($A$25:$A$126, MATCH(1,(EW25:EW126=SMALL(EW25:EW126,3))*(COUNTIF(EW6:EW7, $A$25:$A$126)=0),0)), ""),""),"")} | EX8: {=IFERROR(IF(SMALL(EX25:EX126,3)<=$A$8*SMALL(EX25:EX126,1),IFERROR(INDEX($A$25:$A$126, MATCH(1,(EX25:EX126=SMALL(EX25:EX126,3))*(COUNTIF(EX6:EX7, $A$25:$A$126)=0),0)), ""),""),"")} | EY8: {=IFERROR(IF(SMALL(EY25:EY126,3)<=$A$8*SMALL(EY25:EY126,1),IFERROR(INDEX($A$25:$A$126, MATCH(1,(EY25:EY126=SMALL(EY25:EY126,3))*(COUNTIF(EY6:EY7, $A$25:$A$126)=0),0)), ""),""),"")} | EZ8: {=IFERROR(IF(SMALL(EZ25:EZ126,3)<=$A$8*SMALL(EZ25:EZ126,1),IFERROR(INDEX($A$25:$A$126, MATCH(1,(EZ25:EZ126=SMALL(EZ25:EZ126,3))*(COUNTIF(EZ6:EZ7, $A$25:$A$126)=0),0)), ""),""),"")} | ... IJ8: {=IFERROR(IF(SMALL(IJ25:IJ126,3)<=$A$8*SMALL(IJ25:IJ126,1),IFERROR(INDEX($A$25:$A$126, MATCH(1,(IJ25:IJ126=SMALL(IJ25:IJ126,3))*(COUNTIF(IJ6:IJ7, $A$25:$A$126)=0),0)), ""),""),"")} | IK8: {=IFERROR(IF(SMALL(IK25:IK200,3)<=$A$8*SMALL(IK25:IK200,1),IFERROR(INDEX($A$25:$A$200, MATCH(1,(IK25:IK200=SMALL(IK25:IK200,3))*(COUNTIF(IK6:IK7, $A$25:$A$200)=0),0)), ""),""),"")} -> BAD-SLAM* | IL8: {=IFERROR(IF(SMALL(IL25:IL200,3)<=$A$8*SMALL(IL25:IL200,1),IFERROR(INDEX($A$25:$A$200, MATCH(1,(IL25:IL200=SMALL(IL25:IL200,3))*(COUNTIF(IL6:IL7, $A$25:$A$200)=0),0)), ""),""),"")} | IM8: {=IFERROR(IF(SMALL(IM25:IM200,3)<=$A$8*SMALL(IM25:IM200,1),IFERROR(INDEX($A$25:$A$200, MATCH(1,(IM25:IM200=SMALL(IM25:IM200,3))*(COUNTIF(IM6:IM7, $A$25:$A$200)=0),0)), ""),""),"")} | IN8: {=IFERROR(IF(SMALL(IN25:IN200,3)<=$A$8*SMALL(IN25:IN200,1),IFERROR(INDEX($A$25:$A$200, MATCH(1,(IN25:IN200=SMALL(IN25:IN200,3))*(COUNTIF(IN6:IN7, $A$25:$A$200)=0),0)), ""),""),"")} | IO8: {=IFERROR(IF(SMALL(IO25:IO200,3)<=$A$8*SMALL(IO25:IO200,1),IFERROR(INDEX($A$25:$A$200, MATCH(1,(IO25:IO200=SMALL(IO25:IO200,3))*(COUNTIF(IO6:IO7, $A$25:$A$200)=0),0)), ""),""),"")} | IP8: {=IFERROR(IF(SMALL(IP25:IP200,3)<=$A$8*SMALL(IP25:IP200,1),IFERROR(INDEX($A$25:$A$200, MATCH(1,(IP25:IP200=SMALL(IP25:IP200,3))*(COUNTIF(IP6:IP7, $A$25:$A$200)=0),0)), ""),""),"")} | IQ8: {=IFERROR(IF(SMALL(IQ25:IQ200,3)<=$A$8*SMALL(IQ25:IQ200,1),IFERROR(INDEX($A$25:$A$200, MATCH(1,(IQ25:IQ200=SMALL(IQ25:IQ200,3))*(COUNTIF(IQ6:IQ7, $A$25:$A$200)=0),0)), ""),""),"")} | IR8: {=IFERROR(IF(SMALL(IR25:IR200,3)<=$A$8*SMALL(IR25:IR200,1),IFERROR(INDEX($A$25:$A$200, MATCH(1,(IR25:IR200=SMALL(IR25:IR200,3))*(COUNTIF(IR6:IR7, $A$25:$A$200)=0),0)), ""),""),"")} | ... AGQ8: {=IFERROR(IF(SMALL(AGQ25:AGQ200,3)<=$A$8*SMALL(AGQ25:AGQ200,1),IFERROR(INDEX($A$25:$A$200, MATCH(1,(AGQ25:AGQ200=SMALL(AGQ25:AGQ200,3))*(COUNTIF(AGQ6:AGQ7, $A$25:$A$200)=0),0)), ""),""),"")}
A9: do menor erro | B9: {=IFERROR(IF(SMALL(B25:B118,3)<=$A$8*SMALL(B25:B118,1),IFERROR(INDEX($A$25:$A$118, MATCH(1,(B25:B118=SMALL(B25:B118,3))*(COUNTIF(B6:B8, $A$25:$A$118)=0),0)), ""),""),"")} | C9: {=IFERROR(IF(SMALL(C25:C118,3)<=$A$8*SMALL(C25:C118,1),IFERROR(INDEX($A$25:$A$118, MATCH(1,(C25:C118=SMALL(C25:C118,3))*(COUNTIF(C6:C8, $A$25:$A$118)=0),0)), ""),""),"")} | D9: {=IFERROR(IF(SMALL(D25:D118,3)<=$A$8*SMALL(D25:D118,1),IFERROR(INDEX($A$25:$A$118, MATCH(1,(D25:D118=SMALL(D25:D118,3))*(COUNTIF(D6:D8, $A$25:$A$118)=0),0)), ""),""),"")} | E9: {=IFERROR(IF(SMALL(E25:E118,3)<=$A$8*SMALL(E25:E118,1),IFERROR(INDEX($A$25:$A$118, MATCH(1,(E25:E118=SMALL(E25:E118,3))*(COUNTIF(E6:E8, $A$25:$A$118)=0),0)), ""),""),"")} | F9: {=IFERROR(IF(SMALL(F25:F118,3)<=$A$8*SMALL(F25:F118,1),IFERROR(INDEX($A$25:$A$118, MATCH(1,(F25:F118=SMALL(F25:F118,3))*(COUNTIF(F6:F8, $A$25:$A$118)=0),0)), ""),""),"")} | G9: {=IFERROR(IF(SMALL(G25:G118,3)<=$A$8*SMALL(G25:G118,1),IFERROR(INDEX($A$25:$A$118, MATCH(1,(G25:G118=SMALL(G25:G118,3))*(COUNTIF(G6:G8, $A$25:$A$118)=0),0)), ""),""),"")} | H9: {=IFERROR(IF(SMALL(H25:H118,3)<=$A$8*SMALL(H25:H118,1),IFERROR(INDEX($A$25:$A$118, MATCH(1,(H25:H118=SMALL(H25:H118,3))*(COUNTIF(H6:H8, $A$25:$A$118)=0),0)), ""),""),"")} | I9: {=IFERROR(IF(SMALL(I25:I118,3)<=$A$8*SMALL(I25:I118,1),IFERROR(INDEX($A$25:$A$118, MATCH(1,(I25:I118=SMALL(I25:I118,3))*(COUNTIF(I6:I8, $A$25:$A$118)=0),0)), ""),""),"")} | ... DZ9: {=IFERROR(IF(SMALL(DZ25:DZ118,3)<=$A$8*SMALL(DZ25:DZ118,1),IFERROR(INDEX($A$25:$A$118, MATCH(1,(DZ25:DZ118=SMALL(DZ25:DZ118,3))*(COUNTIF(DZ6:DZ8, $A$25:$A$118)=0),0)), ""),""),"")} | EC9: {=IFERROR(IF(SMALL(EC25:EC118,3)<=$A$8*SMALL(EC25:EC118,1),IFERROR(INDEX($A$25:$A$118, MATCH(1,(EC25:EC118=SMALL(EC25:EC118,3))*(COUNTIF(EC6:EC8, $A$25:$A$118)=0),0)), ""),""),"")} | EF9: {=IFERROR(IF(SMALL(EF25:EF118,3)<=$A$8*SMALL(EF25:EF118,1),IFERROR(INDEX($A$25:$A$118, MATCH(1,(EF25:EF118=SMALL(EF25:EF118,3))*(COUNTIF(EF6:EF8, $A$25:$A$118)=0),0)), ""),""),"")} | EH9: {=IFERROR(IF(SMALL(EH25:EH118,3)<=$A$8*SMALL(EH25:EH118,1),IFERROR(INDEX($A$25:$A$118, MATCH(1,(EH25:EH118=SMALL(EH25:EH118,3))*(COUNTIF(EH6:EH8, $A$25:$A$118)=0),0)), ""),""),"")} | EI9: {=IFERROR(IF(SMALL(EI25:EI118,3)<=$A$8*SMALL(EI25:EI118,1),IFERROR(INDEX($A$25:$A$118, MATCH(1,(EI25:EI118=SMALL(EI25:EI118,3))*(COUNTIF(EI6:EI8, $A$25:$A$118)=0),0)), ""),""),"")} | EJ9: {=IFERROR(IF(SMALL(EJ25:EJ118,3)<=$A$8*SMALL(EJ25:EJ118,1),IFERROR(INDEX($A$25:$A$118, MATCH(1,(EJ25:EJ118=SMALL(EJ25:EJ118,3))*(COUNTIF(EJ6:EJ8, $A$25:$A$118)=0),0)), ""),""),"")} | EK9: {=IFERROR(IF(SMALL(EK25:EK118,3)<=$A$8*SMALL(EK25:EK118,1),IFERROR(INDEX($A$25:$A$118, MATCH(1,(EK25:EK118=SMALL(EK25:EK118,3))*(COUNTIF(EK6:EK8, $A$25:$A$118)=0),0)), ""),""),"")} | EL9: {=IFERROR(IF(SMALL(EL25:EL118,3)<=$A$8*SMALL(EL25:EL118,1),IFERROR(INDEX($A$25:$A$118, MATCH(1,(EL25:EL118=SMALL(EL25:EL118,3))*(COUNTIF(EL6:EL8, $A$25:$A$118)=0),0)), ""),""),"")} | EM9: {=IFERROR(IF(SMALL(EM25:EM118,3)<=$A$8*SMALL(EM25:EM118,1),IFERROR(INDEX($A$25:$A$118, MATCH(1,(EM25:EM118=SMALL(EM25:EM118,3))*(COUNTIF(EM6:EM8, $A$25:$A$118)=0),0)), ""),""),"")} | EN9: {=IFERROR(IF(SMALL(EN25:EN118,3)<=$A$8*SMALL(EN25:EN118,1),IFERROR(INDEX($A$25:$A$118, MATCH(1,(EN25:EN118=SMALL(EN25:EN118,3))*(COUNTIF(EN6:EN8, $A$25:$A$118)=0),0)), ""),""),"")} | EO9: {=IFERROR(IF(SMALL(EO25:EO118,3)<=$A$8*SMALL(EO25:EO118,1),IFERROR(INDEX($A$25:$A$118, MATCH(1,(EO25:EO118=SMALL(EO25:EO118,3))*(COUNTIF(EO6:EO8, $A$25:$A$118)=0),0)), ""),""),"")} | ... ER9: {=IFERROR(IF(SMALL(ER25:ER118,3)<=$A$8*SMALL(ER25:ER118,1),IFERROR(INDEX($A$25:$A$118, MATCH(1,(ER25:ER118=SMALL(ER25:ER118,3))*(COUNTIF(ER6:ER8, $A$25:$A$118)=0),0)), ""),""),"")} | ES9: {=IFERROR(IF(SMALL(ES25:ES126,3)<=$A$8*SMALL(ES25:ES126,1),IFERROR(INDEX($A$25:$A$126, MATCH(1,(ES25:ES126=SMALL(ES25:ES126,3))*(COUNTIF(ES6:ES8, $A$25:$A$126)=0),0)), ""),""),"")} | ET9: {=IFERROR(IF(SMALL(ET25:ET126,3)<=$A$8*SMALL(ET25:ET126,1),IFERROR(INDEX($A$25:$A$126, MATCH(1,(ET25:ET126=SMALL(ET25:ET126,3))*(COUNTIF(ET6:ET8, $A$25:$A$126)=0),0)), ""),""),"")} | EU9: {=IFERROR(IF(SMALL(EU25:EU126,3)<=$A$8*SMALL(EU25:EU126,1),IFERROR(INDEX($A$25:$A$126, MATCH(1,(EU25:EU126=SMALL(EU25:EU126,3))*(COUNTIF(EU6:EU8, $A$25:$A$126)=0),0)), ""),""),"")} | EV9: {=IFERROR(IF(SMALL(EV25:EV126,3)<=$A$8*SMALL(EV25:EV126,1),IFERROR(INDEX($A$25:$A$126, MATCH(1,(EV25:EV126=SMALL(EV25:EV126,3))*(COUNTIF(EV6:EV8, $A$25:$A$126)=0),0)), ""),""),"")} | EW9: {=IFERROR(IF(SMALL(EW25:EW126,3)<=$A$8*SMALL(EW25:EW126,1),IFERROR(INDEX($A$25:$A$126, MATCH(1,(EW25:EW126=SMALL(EW25:EW126,3))*(COUNTIF(EW6:EW8, $A$25:$A$126)=0),0)), ""),""),"")} | EX9: {=IFERROR(IF(SMALL(EX25:EX126,3)<=$A$8*SMALL(EX25:EX126,1),IFERROR(INDEX($A$25:$A$126, MATCH(1,(EX25:EX126=SMALL(EX25:EX126,3))*(COUNTIF(EX6:EX8, $A$25:$A$126)=0),0)), ""),""),"")} | EY9: {=IFERROR(IF(SMALL(EY25:EY126,3)<=$A$8*SMALL(EY25:EY126,1),IFERROR(INDEX($A$25:$A$126, MATCH(1,(EY25:EY126=SMALL(EY25:EY126,3))*(COUNTIF(EY6:EY8, $A$25:$A$126)=0),0)), ""),""),"")} | EZ9: {=IFERROR(IF(SMALL(EZ25:EZ126,3)<=$A$8*SMALL(EZ25:EZ126,1),IFERROR(INDEX($A$25:$A$126, MATCH(1,(EZ25:EZ126=SMALL(EZ25:EZ126,3))*(COUNTIF(EZ6:EZ8, $A$25:$A$126)=0),0)), ""),""),"")} | ... IJ9: {=IFERROR(IF(SMALL(IJ25:IJ126,3)<=$A$8*SMALL(IJ25:IJ126,1),IFERROR(INDEX($A$25:$A$126, MATCH(1,(IJ25:IJ126=SMALL(IJ25:IJ126,3))*(COUNTIF(IJ6:IJ8, $A$25:$A$126)=0),0)), ""),""),"")} | IK9: {=IFERROR(IF(SMALL(IK25:IK200,3)<=$A$8*SMALL(IK25:IK200,1),IFERROR(INDEX($A$25:$A$200, MATCH(1,(IK25:IK200=SMALL(IK25:IK200,3))*(COUNTIF(IK6:IK8, $A$25:$A$200)=0),0)), ""),""),"")} | IL9: {=IFERROR(IF(SMALL(IL25:IL200,3)<=$A$8*SMALL(IL25:IL200,1),IFERROR(INDEX($A$25:$A$200, MATCH(1,(IL25:IL200=SMALL(IL25:IL200,3))*(COUNTIF(IL6:IL8, $A$25:$A$200)=0),0)), ""),""),"")} | IM9: {=IFERROR(IF(SMALL(IM25:IM200,3)<=$A$8*SMALL(IM25:IM200,1),IFERROR(INDEX($A$25:$A$200, MATCH(1,(IM25:IM200=SMALL(IM25:IM200,3))*(COUNTIF(IM6:IM8, $A$25:$A$200)=0),0)), ""),""),"")} | IN9: {=IFERROR(IF(SMALL(IN25:IN200,3)<=$A$8*SMALL(IN25:IN200,1),IFERROR(INDEX($A$25:$A$200, MATCH(1,(IN25:IN200=SMALL(IN25:IN200,3))*(COUNTIF(IN6:IN8, $A$25:$A$200)=0),0)), ""),""),"")} | IO9: {=IFERROR(IF(SMALL(IO25:IO200,3)<=$A$8*SMALL(IO25:IO200,1),IFERROR(INDEX($A$25:$A$200, MATCH(1,(IO25:IO200=SMALL(IO25:IO200,3))*(COUNTIF(IO6:IO8, $A$25:$A$200)=0),0)), ""),""),"")} | IP9: {=IFERROR(IF(SMALL(IP25:IP200,3)<=$A$8*SMALL(IP25:IP200,1),IFERROR(INDEX($A$25:$A$200, MATCH(1,(IP25:IP200=SMALL(IP25:IP200,3))*(COUNTIF(IP6:IP8, $A$25:$A$200)=0),0)), ""),""),"")} | IQ9: {=IFERROR(IF(SMALL(IQ25:IQ200,3)<=$A$8*SMALL(IQ25:IQ200,1),IFERROR(INDEX($A$25:$A$200, MATCH(1,(IQ25:IQ200=SMALL(IQ25:IQ200,3))*(COUNTIF(IQ6:IQ8, $A$25:$A$200)=0),0)), ""),""),"")} | IR9: {=IFERROR(IF(SMALL(IR25:IR200,3)<=$A$8*SMALL(IR25:IR200,1),IFERROR(INDEX($A$25:$A$200, MATCH(1,(IR25:IR200=SMALL(IR25:IR200,3))*(COUNTIF(IR6:IR8, $A$25:$A$200)=0),0)), ""),""),"")} | ... AGQ9: {=IFERROR(IF(SMALL(AGQ25:AGQ200,3)<=$A$8*SMALL(AGQ25:AGQ200,1),IFERROR(INDEX($A$25:$A$200, MATCH(1,(AGQ25:AGQ200=SMALL(AGQ25:AGQ200,3))*(COUNTIF(AGQ6:AGQ8, $A$25:$A$200)=0),0)), ""),""),"")}
