<?xml version="1.0"?>
<robot xmlns:xacro="http://www.ros.org/wiki/xacro">

  <xacro:macro name="diffbot" params="prefix">

  <!-- Constants for robot dimensions -->
  <xacro:property name="PI" value="3.1415926535897931"/>
  <xacro:property name="base_mass" value="0.3" /> <!-- arbitrary value for base mass -->
  <xacro:property name="base_width" value="0.401" />
  <xacro:property name="base_length" value="0.52" />
  <xacro:property name="base_height" value="0.215" />
  <xacro:property name="wheel_mass" value="0.3" /> <!-- arbitrary value for wheel mass -->
  <xacro:property name="wheel_len" value="0.058" />
  <xacro:property name="wheel_radius" value="0.0875" />
  <xacro:property name="caster_xoff" value="0.182"/> <!-- about  442mm from front, which is about 182mm from center -->
  <xacro:property name="caster_wheel_mass" value="0.1" /> <!-- arbitrary value for caster wheel mass -->
  <xacro:property name="caster_wheel_radius" value="0.05" />
  <xacro:property name="z_offset" value="-${base_height/2}" /> <!-- Space btw top of beam and the each joint -->

  <xacro:property name="wheel_width" value="0.058"/> <!-- script edited just so this value is used to offset the wheel from the main body -->
  <xacro:property name="wheel_ygap" value="0.008"/> <!-- y distance from wheel center to body -->
  <xacro:property name="wheel_zoff" value="0.120"/> <!-- Wheel Z offset from center (base_height/2+0.0125) -->
  <xacro:property name="wheel_xoff" value="0.105"/> <!-- About 155 mm from front, about 105mm from center -->


  <xacro:property name="lidar_radius" value="0.037"/> <!-- Radius for the cylinder representing the LiDAR body -->
  <xacro:property name="front_to_lidar_xoff" value="0.076"/> <!-- Radius for the cylinder representing the LiDAR body -->
  <xacro:property name="lidar_height" value="0.13988"/> <!-- Obtained by the distance from the acrylic base to the LiDAR center *2 -->
  <xacro:property name="lidar_base_height" value="0.0225"/> <!-- height of the LiDAR's base plate accessory -->

  <xacro:property name="realsense_xoff" value="0.2630449"/> 
  <xacro:property name="realsense_yoff" value="0.0175"/> 
  <xacro:property name="realsense_zoff" value="0.021"/> <!-- negative offset from acrylic Lidar's base -->


  <!-- Base Link -->
  <link name="${prefix}base_link">
    <collision>
      <!-- <origin xyz="0 0 0" rpy="0 0 0"/> -->
      <geometry>
        <box size="${base_length} ${base_width} ${base_height}"/>
      </geometry>
    </collision>

    <visual>
      <material name="Cyan">
          <color rgba="0 1.0 1.0 1.0"/>
      </material>
      <!-- <origin xyz="0 0 ${base_height/2}" rpy="0 0 0"/> -->
      <geometry>
        <box size="${base_length} ${base_width} ${base_height}"/>
      </geometry>
      <material name="orange"/>
    </visual>

    <inertial>
      <origin xyz="0 0 0" rpy="0 0 0"/>
      <mass value="${base_mass}"/>
      <inertia
        ixx="${base_mass / 12.0 * (base_length*base_length + base_height*base_height)}" ixy="0.0" ixz="0.0"
        iyy="${base_mass / 12.0 * (base_height*base_height + base_width*base_width)}" iyz="0.0"
        izz="${base_mass / 12.0 * (base_width*base_width + base_length*base_length)}"/>
      </inertial>
    </link>


    <!-- <joint name="${prefix}base_link_joint" type="continuous">
      <parent link="base_link"/>
      <child link="${prefix}base_link"/>
      <origin xyz="0 0 0" rpy="0 0 ${PI/2}"/>
      <axis xyz="0 0 0"/>
    </joint> -->

    <joint name="${prefix}left_wheel_joint" type="continuous">
      <parent link="${prefix}base_link"/>
      <child link="${prefix}left_wheel"/>
      <origin xyz="${wheel_xoff} ${1*(base_width/2+wheel_ygap+wheel_width/2)} ${-wheel_zoff}" rpy="0 0 0"/>
      <axis xyz="0 1 0"/>
      <dynamics damping="0.2"/>
      <limit effort="100" velocity="1.0"/>
    </joint>

    <!-- left wheel Link -->
    <link name="${prefix}left_wheel">
      <collision>
        <origin xyz="0 0 0" rpy="${PI/2} 0 0"/>
        <geometry>
          <cylinder length="${wheel_len}" radius="${wheel_radius}"/>
        </geometry>
      </collision>

      <visual>
        <origin xyz="0 0 0" rpy="${PI/2} 0 0"/>
        <geometry>
          <cylinder length="${wheel_len}" radius="${wheel_radius}"/>
        </geometry>
          <material name="Gray">
              <color rgba="0.5 0.5 0.5 1.0"/>
          </material>
      </visual>

      <inertial>
        <origin xyz="0 0 0" rpy="${PI/2} 0 0"/>
        <mass value="${wheel_mass}"/>
        <inertia
          ixx="${wheel_mass / 12.0 * (3*wheel_radius*wheel_radius + wheel_len*wheel_len)}" ixy="0.0" ixz="0.0"
          iyy="${wheel_mass / 12.0 * (3*wheel_radius*wheel_radius + wheel_len*wheel_len)}" iyz="0.0"
          izz="${wheel_mass / 2.0 * wheel_radius*wheel_radius}"/>
        </inertial>
      </link>

    <joint name="${prefix}right_wheel_joint" type="continuous">
      <parent link="${prefix}base_link"/>
      <child link="${prefix}right_wheel"/>
      <origin xyz="${wheel_xoff} ${-1*(base_width/2+wheel_ygap+wheel_width/2)} ${-wheel_zoff}" rpy="0 0 0"/>
      <axis xyz="0 1 0"/>
      <dynamics damping="0.2"/>
      <limit effort="100" velocity="1.0"/>
    </joint>

    <!-- right wheel Link -->
    <link name="${prefix}right_wheel">
      <collision>
        <origin xyz="0 0 0" rpy="${PI/2} 0 0"/>
        <geometry>
          <cylinder length="${wheel_len}" radius="${wheel_radius}"/>
        </geometry>
      </collision>

      <visual>
        <origin xyz="0 0 0" rpy="${PI/2} 0 0"/>
        <geometry>
          <cylinder length="${wheel_len}" radius="${wheel_radius}"/>
        </geometry>
          <material name="Gray">
              <color rgba="0.5 0.5 0.5 1.0"/>
          </material>
      </visual>

      <inertial>
        <origin xyz="0 0 0" rpy="${PI/2} 0 0"/>
        <mass value="${wheel_mass}"/>
        <inertia
          ixx="${wheel_mass / 12.0 * (3*wheel_radius*wheel_radius + wheel_len*wheel_len)}" ixy="0.0" ixz="0.0"
          iyy="${wheel_mass / 12.0 * (3*wheel_radius*wheel_radius + wheel_len*wheel_len)}" iyz="0.0"
          izz="${wheel_mass / 2.0 * wheel_radius*wheel_radius}"/>
        </inertial>
      </link>

    <!-- <joint name="${prefix}caster_frontal_wheel_joint" type="fixed">
      <parent link="${prefix}base_link"/>
      <child link="${prefix}caster_frontal_wheel"/>
      <origin xyz="${-caster_xoff} 0.0 ${-(base_height/2+caster_wheel_radius)}" rpy="0 0 0"/>
    </joint> -->

    <!-- caster frontal wheel Link -->
    <!-- <link name="${prefix}caster_frontal_wheel">
      <collision>
        <origin xyz="0 0 0" rpy="0 0 0"/>
        <geometry>
          <sphere radius="${caster_wheel_radius}"/>
        </geometry>
      </collision>

      <visual>
        <origin xyz="0 0 0" rpy="0 0 0"/>
        <geometry>
          <sphere radius="${caster_wheel_radius}"/>
        </geometry>
        <material name="Cyan">
        <color rgba="0 1.0 1.0 1.0"/>
        </material>
      </visual>

      <inertial>
        <origin xyz="0 0 0" rpy="0 0 0"/>
        <mass value="${caster_wheel_mass}"/>
        <inertia
          ixx="${caster_wheel_mass * 0.4 * (caster_wheel_radius * caster_wheel_radius)}" ixy="0.0" ixz="0.0"
          iyy="${caster_wheel_mass * 0.4 * (caster_wheel_radius * caster_wheel_radius)}" iyz="0.0"
          izz="${caster_wheel_mass * 0.4 * (caster_wheel_radius * caster_wheel_radius)}"/>
        </inertial>
      </link> -->

    <joint name="${prefix}caster_rear_wheel_joint" type="fixed">
      <parent link="${prefix}base_link"/>
      <child link="${prefix}caster_rear_wheel"/>
      <origin xyz="${-caster_xoff} 0.0 ${-(base_height/2+caster_wheel_radius)}" rpy="0 0 0"/>
    </joint>

    <!-- caster rear wheel Link -->
    <link name="${prefix}caster_rear_wheel">
      <collision>
        <origin xyz="0 0 0" rpy="0 0 0"/>
        <geometry>
          <sphere radius="${caster_wheel_radius}"/>
        </geometry>
      </collision>

      <visual>
        <origin xyz="0 0 0" rpy="0 0 0"/>
        <geometry>
          <sphere radius="${caster_wheel_radius}"/>
        </geometry>
        <material name="Gray">
            <color rgba="0.5 0.5 0.5 1.0"/>
        </material>
      </visual>

      <inertial>
        <origin xyz="0 0 0" rpy="0 0 0"/>
        <mass value="${caster_wheel_mass}"/>
        <inertia
          ixx="${caster_wheel_mass * 0.4 * (caster_wheel_radius * caster_wheel_radius)}" ixy="0.0" ixz="0.0"
          iyy="${caster_wheel_mass * 0.4 * (caster_wheel_radius * caster_wheel_radius)}" iyz="0.0"
          izz="${caster_wheel_mass * 0.4 * (caster_wheel_radius * caster_wheel_radius)}"/>
        </inertial>
      </link>

      

  </xacro:macro>

</robot>